Workbook

Sheet ÖZET
A1: Sorumlu bazında iş sayısı (VKN aralığına göre; Vergilendirme bölümü aralıkları — kaynak: kullanıcının aracındaki tablo)
A3: SORUMLU | B3: 03.01 | C3: 03.02 | D3: 03.03 | E3: 03.04 | F3: 03.05 | G3: 03.06 | H3: 03.08 | I3: 05.01 | J3: 05.02 | K3: 05.03 | L3: 05.04 | M3: 05.05 | N3: 06.01 | O3: 06.02 | P3: 06.03 | Q3: 06.04 | R3: 06.05 | S3: 08.04 | T3: 09.01 | U3: 09.02 | V3: 09.03 | W3: 09.04 | X3: 09.05 | Y3: TOPLAM
A4: Nalan ŞERİF | B4: =COUNTIFS('03 VERGİ İNCELEME RAPORU'!$B:$B,$A4,'03 VERGİ İNCELEME RAPORU'!$A:$A,"03.01*") -> 1 | C4: =COUNTIFS('03 VERGİ İNCELEME RAPORU'!$B:$B,$A4,'03 VERGİ İNCELEME RAPORU'!$A:$A,"03.02*") -> 0 | D4: =COUNTIFS('03 VERGİ İNCELEME RAPORU'!$B:$B,$A4,'03 VERGİ İNCELEME RAPORU'!$A:$A,"03.03*") -> 8 | E4: =COUNTIFS('03 VERGİ İNCELEME RAPORU'!$B:$B,$A4,'03 VERGİ İNCELEME RAPORU'!$A:$A,"03.04*") -> 0 | F4: =COUNTIFS('03 VERGİ İNCELEME RAPORU'!$B:$B,$A4,'03 VERGİ İNCELEME RAPORU'!$A:$A,"03.05*") -> 0 | G4: =COUNTIFS('03 VERGİ İNCELEME RAPORU'!$B:$B,$A4,'03 VERGİ İNCELEME RAPORU'!$A:$A,"03.06*") -> 0 | H4: =COUNTIFS('03 VERGİ İNCELEME RAPORU'!$B:$B,$A4,'03 VERGİ İNCELEME RAPORU'!$A:$A,"03.08*") -> 0 | I4: =COUNTIFS('05 TAKDİRİ SEVK İŞLEMLERİ'!$B:$B,$A4,'05 TAKDİRİ SEVK İŞLEMLERİ'!$A:$A,"05.01*") -> 0 | J4: =COUNTIFS('05 TAKDİRİ SEVK İŞLEMLERİ'!$B:$B,$A4,'05 TAKDİRİ SEVK İŞLEMLERİ'!$A:$A,"05.02*") -> 0 | K4: =COUNTIFS('05 TAKDİRİ SEVK İŞLEMLERİ'!$B:$B,$A4,'05 TAKDİRİ SEVK İŞLEMLERİ'!$A:$A,"05.03*") -> 0 | L4: =COUNTIFS('05 TAKDİRİ SEVK İŞLEMLERİ'!$B:$B,$A4,'05 TAKDİRİ SEVK İŞLEMLERİ'!$A:$A,"05.04*") -> 0 | M4: =COUNTIFS('05 TAKDİRİ SEVK İŞLEMLERİ'!$B:$B,$A4,'05 TAKDİRİ SEVK İŞLEMLERİ'!$A:$A,"05.05*") -> 0 | N4: =COUNTIFS('06 VERGİ CEZA İHBARNAMELERİ'!$B:$B,$A4,'06 VERGİ CEZA İHBARNAMELERİ'!$A:$A,"06.01*") -> 5 | O4: =COUNTIFS('06 VERGİ CEZA İHBARNAMELERİ'!$B:$B,$A4,'06 VERGİ CEZA İHBARNAMELERİ'!$A:$A,"06.02*") -> 13 | P4: =COUNTIFS('06 VERGİ CEZA İHBARNAMELERİ'!$B:$B,$A4,'06 VERGİ CEZA İHBARNAMELERİ'!$A:$A,"06.03*") -> 3 | Q4: =COUNTIFS('06 VERGİ CEZA İHBARNAMELERİ'!$B:$B,$A4,'06 VERGİ CEZA İHBARNAMELERİ'!$A:$A,"06.04*") -> 2 | R4: =COUNTIFS('06 VERGİ CEZA İHBARNAMELERİ'!$B:$B,$A4,'06 VERGİ CEZA İHBARNAMELERİ'!$A:$A,"06.05*") -> 8 | S4: =COUNTIFS('08 SÜREKSİZ YÜKÜMLÜLÜKLER'!$B:$B,$A4,'08 SÜREKSİZ YÜKÜMLÜLÜKLER'!$A:$A,"08.04*") -> 0 | T4: =COUNTIFS('09 KANUNİ SÜRESİNDEN SONRA VERİ'!$B:$B,$A4,'09 KANUNİ SÜRESİNDEN SONRA VERİ'!$A:$A,"09.01*") -> 0 | U4: =COUNTIFS('09 KANUNİ SÜRESİNDEN SONRA VERİ'!$B:$B,$A4,'09 KANUNİ SÜRESİNDEN SONRA VERİ'!$A:$A,"09.02*") -> 3 | V4: =COUNTIFS('09 KANUNİ SÜRESİNDEN SONRA VERİ'!$B:$B,$A4,'09 KANUNİ SÜRESİNDEN SONRA VERİ'!$A:$A,"09.03*") -> 0 | W4: =COUNTIFS('09 KANUNİ SÜRESİNDEN SONRA VERİ'!$B:$B,$A4,'09 KANUNİ SÜRESİNDEN SONRA VERİ'!$A:$A,"09.04*") -> 0 | X4: =COUNTIFS('09 KANUNİ SÜRESİNDEN SONRA VERİ'!$B:$B,$A4,'09 KANUNİ SÜRESİNDEN SONRA VERİ'!$A:$A,"09.05*") -> 0 | Y4: =SUM(B4:X4) -> 43
A5: Özge TARIM | B5: =COUNTIFS('03 VERGİ İNCELEME RAPORU'!$B:$B,$A5,'03 VERGİ İNCELEME RAPORU'!$A:$A,"03.01*") -> 0 | C5: =COUNTIFS('03 VERGİ İNCELEME RAPORU'!$B:$B,$A5,'03 VERGİ İNCELEME RAPORU'!$A:$A,"03.02*") -> 0 | D5: =COUNTIFS('03 VERGİ İNCELEME RAPORU'!$B:$B,$A5,'03 VERGİ İNCELEME RAPORU'!$A:$A,"03.03*") -> 0 | E5: =COUNTIFS('03 VERGİ İNCELEME RAPORU'!$B:$B,$A5,'03 VERGİ İNCELEME RAPORU'!$A:$A,"03.04*") -> 0 | F5: =COUNTIFS('03 VERGİ İNCELEME RAPORU'!$B:$B,$A5,'03 VERGİ İNCELEME RAPORU'!$A:$A,"03.05*") -> 0 | G5: =COUNTIFS('03 VERGİ İNCELEME RAPORU'!$B:$B,$A5,'03 VERGİ İNCELEME RAPORU'!$A:$A,"03.06*") -> 0 | H5: =COUNTIFS('03 VERGİ İNCELEME RAPORU'!$B:$B,$A5,'03 VERGİ İNCELEME RAPORU'!$A:$A,"03.08*") -> 0 | I5: =COUNTIFS('05 TAKDİRİ SEVK İŞLEMLERİ'!$B:$B,$A5,'05 TAKDİRİ SEVK İŞLEMLERİ'!$A:$A,"05.01*") -> 0 | J5: =COUNTIFS('05 TAKDİRİ SEVK İŞLEMLERİ'!$B:$B,$A5,'05 TAKDİRİ SEVK İŞLEMLERİ'!$A:$A,"05.02*") -> 0 | K5: =COUNTIFS('05 TAKDİRİ SEVK İŞLEMLERİ'!$B:$B,$A5,'05 TAKDİRİ SEVK İŞLEMLERİ'!$A:$A,"05.03*") -> 0 | L5: =COUNTIFS('05 TAKDİRİ SEVK İŞLEMLERİ'!$B:$B,$A5,'05 TAKDİRİ SEVK İŞLEMLERİ'!$A:$A,"05.04*") -> 0 | M5: =COUNTIFS('05 TAKDİRİ SEVK İŞLEMLERİ'!$B:$B,$A5,'05 TAKDİRİ SEVK İŞLEMLERİ'!$A:$A,"05.05*") -> 1 | N5: =COUNTIFS('06 VERGİ CEZA İHBARNAMELERİ'!$B:$B,$A5,'06 VERGİ CEZA İHBARNAMELERİ'!$A:$A,"06.01*") -> 43 | O5: =COUNTIFS('06 VERGİ CEZA İHBARNAMELERİ'!$B:$B,$A5,'06 VERGİ CEZA İHBARNAMELERİ'!$A:$A,"06.02*") -> 13 | P5: =COUNTIFS('06 VERGİ CEZA İHBARNAMELERİ'!$B:$B,$A5,'06 VERGİ CEZA İHBARNAMELERİ'!$A:$A,"06.03*") -> 9 | Q5: =COUNTIFS('06 VERGİ CEZA İHBARNAMELERİ'!$B:$B,$A5,'06 VERGİ CEZA İHBARNAMELERİ'!$A:$A,"06.04*") -> 2 | R5: =COUNTIFS('06 VERGİ CEZA İHBARNAMELERİ'!$B:$B,$A5,'06 VERGİ CEZA İHBARNAMELERİ'!$A:$A,"06.05*") -> 1 | S5: =COUNTIFS('08 SÜREKSİZ YÜKÜMLÜLÜKLER'!$B:$B,$A5,'08 SÜREKSİZ YÜKÜMLÜLÜKLER'!$A:$A,"08.04*") -> 0 | T5: =COUNTIFS('09 KANUNİ SÜRESİNDEN SONRA VERİ'!$B:$B,$A5,'09 KANUNİ SÜRESİNDEN SONRA VERİ'!$A:$A,"09.01*") -> 0 | U5: =COUNTIFS('09 KANUNİ SÜRESİNDEN SONRA VERİ'!$B:$B,$A5,'09 KANUNİ SÜRESİNDEN SONRA VERİ'!$A:$A,"09.02*") -> 0 | V5: =COUNTIFS('09 KANUNİ SÜRESİNDEN SONRA VERİ'!$B:$B,$A5,'09 KANUNİ SÜRESİNDEN SONRA VERİ'!$A:$A,"09.03*") -> 0 | W5: =COUNTIFS('09 KANUNİ SÜRESİNDEN SONRA VERİ'!$B:$B,$A5,'09 KANUNİ SÜRESİNDEN SONRA VERİ'!$A:$A,"09.04*") -> 1 | X5: =COUNTIFS('09 KANUNİ SÜRESİNDEN SONRA VERİ'!$B:$B,$A5,'09 KANUNİ SÜRESİNDEN SONRA VERİ'!$A:$A,"09.05*") -> 0 | Y5: =SUM(B5:X5) -> 70
A6: Halim YARAR | B6: =COUNTIFS('03 VERGİ İNCELEME RAPORU'!$B:$B,$A6,'03 VERGİ İNCELEME RAPORU'!$A:$A,"03.01*") -> 1 | C6: =COUNTIFS('03 VERGİ İNCELEME RAPORU'!$B:$B,$A6,'03 VERGİ İNCELEME RAPORU'!$A:$A,"03.02*") -> 0 | D6: =COUNTIFS('03 VERGİ İNCELEME RAPORU'!$B:$B,$A6,'03 VERGİ İNCELEME RAPORU'!$A:$A,"03.03*") -> 8 | E6: =COUNTIFS('03 VERGİ İNCELEME RAPORU'!$B:$B,$A6,'03 VERGİ İNCELEME RAPORU'!$A:$A,"03.04*") -> 0 | F6: =COUNTIFS('03 VERGİ İNCELEME RAPORU'!$B:$B,$A6,'03 VERGİ İNCELEME RAPORU'!$A:$A,"03.05*") -> 1 | G6: =COUNTIFS('03 VERGİ İNCELEME RAPORU'!$B:$B,$A6,'03 VERGİ İNCELEME RAPORU'!$A:$A,"03.06*") -> 0 | H6: =COUNTIFS('03 VERGİ İNCELEME RAPORU'!$B:$B,$A6,'03 VERGİ İNCELEME RAPORU'!$A:$A,"03.08*") -> 0 | I6: =COUNTIFS('05 TAKDİRİ SEVK İŞLEMLERİ'!$B:$B,$A6,'05 TAKDİRİ SEVK İŞLEMLERİ'!$A:$A,"05.01*") -> 0 | J6: =COUNTIFS('05 TAKDİRİ SEVK İŞLEMLERİ'!$B:$B,$A6,'05 TAKDİRİ SEVK İŞLEMLERİ'!$A:$A,"05.02*") -> 6 | K6: =COUNTIFS('05 TAKDİRİ SEVK İŞLEMLERİ'!$B:$B,$A6,'05 TAKDİRİ SEVK İŞLEMLERİ'!$A:$A,"05.03*") -> 24 | L6: =COUNTIFS('05 TAKDİRİ SEVK İŞLEMLERİ'!$B:$B,$A6,'05 TAKDİRİ SEVK İŞLEMLERİ'!$A:$A,"05.04*") -> 0 | M6: =COUNTIFS('05 TAKDİRİ SEVK İŞLEMLERİ'!$B:$B,$A6,'05 TAKDİRİ SEVK İŞLEMLERİ'!$A:$A,"05.05*") -> 0 | N6: =COUNTIFS('06 VERGİ CEZA İHBARNAMELERİ'!$B:$B,$A6,'06 VERGİ CEZA İHBARNAMELERİ'!$A:$A,"06.01*") -> 3 | O6: =COUNTIFS('06 VERGİ CEZA İHBARNAMELERİ'!$B:$B,$A6,'06 VERGİ CEZA İHBARNAMELERİ'!$A:$A,"06.02*") -> 10 | P6: =COUNTIFS('06 VERGİ CEZA İHBARNAMELERİ'!$B:$B,$A6,'06 VERGİ CEZA İHBARNAMELERİ'!$A:$A,"06.03*") -> 16 | Q6: =COUNTIFS('06 VERGİ CEZA İHBARNAMELERİ'!$B:$B,$A6,'06 VERGİ CEZA İHBARNAMELERİ'!$A:$A,"06.04*") -> 19 | R6: =COUNTIFS('06 VERGİ CEZA İHBARNAMELERİ'!$B:$B,$A6,'06 VERGİ CEZA İHBARNAMELERİ'!$A:$A,"06.05*") -> 4 | S6: =COUNTIFS('08 SÜREKSİZ YÜKÜMLÜLÜKLER'!$B:$B,$A6,'08 SÜREKSİZ YÜKÜMLÜLÜKLER'!$A:$A,"08.04*") -> 0 | T6: =COUNTIFS('09 KANUNİ SÜRESİNDEN SONRA VERİ'!$B:$B,$A6,'09 KANUNİ SÜRESİNDEN SONRA VERİ'!$A:$A,"09.01*") -> 0 | U6: =COUNTIFS('09 KANUNİ SÜRESİNDEN SONRA VERİ'!$B:$B,$A6,'09 KANUNİ SÜRESİNDEN SONRA VERİ'!$A:$A,"09.02*") -> 0 | V6: =COUNTIFS('09 KANUNİ SÜRESİNDEN SONRA VERİ'!$B:$B,$A6,'09 KANUNİ SÜRESİNDEN SONRA VERİ'!$A:$A,"09.03*") -> 0 | W6: =COUNTIFS('09 KANUNİ SÜRESİNDEN SONRA VERİ'!$B:$B,$A6,'09 KANUNİ SÜRESİNDEN SONRA VERİ'!$A:$A,"09.04*") -> 0 | X6: =COUNTIFS('09 KANUNİ SÜRESİNDEN SONRA VERİ'!$B:$B,$A6,'09 KANUNİ SÜRESİNDEN SONRA VERİ'!$A:$A,"09.05*") -> 4 | Y6: =SUM(B6:X6) -> 96
A7: Çağatay TÜRKOĞLU | B7: =COUNTIFS('03 VERGİ İNCELEME RAPORU'!$B:$B,$A7,'03 VERGİ İNCELEME RAPORU'!$A:$A,"03.01*") -> 0 | C7: =COUNTIFS('03 VERGİ İNCELEME RAPORU'!$B:$B,$A7,'03 VERGİ İNCELEME RAPORU'!$A:$A,"03.02*") -> 0 | D7: =COUNTIFS('03 VERGİ İNCELEME RAPORU'!$B:$B,$A7,'03 VERGİ İNCELEME RAPORU'!$A:$A,"03.03*") -> 0 | E7: =COUNTIFS('03 VERGİ İNCELEME RAPORU'!$B:$B,$A7,'03 VERGİ İNCELEME RAPORU'!$A:$A,"03.04*") -> 0 | F7: =COUNTIFS('03 VERGİ İNCELEME RAPORU'!$B:$B,$A7,'03 VERGİ İNCELEME RAPORU'!$A:$A,"03.05*") -> 0 | G7: =COUNTIFS('03 VERGİ İNCELEME RAPORU'!$B:$B,$A7,'03 VERGİ İNCELEME RAPORU'!$A:$A,"03.06*") -> 0 | H7: =COUNTIFS('03 VERGİ İNCELEME RAPORU'!$B:$B,$A7,'03 VERGİ İNCELEME RAPORU'!$A:$A,"03.08*") -> 0 | I7: =COUNTIFS('05 TAKDİRİ SEVK İŞLEMLERİ'!$B:$B,$A7,'05 TAKDİRİ SEVK İŞLEMLERİ'!$A:$A,"05.01*") -> 0 | J7: =COUNTIFS('05 TAKDİRİ SEVK İŞLEMLERİ'!$B:$B,$A7,'05 TAKDİRİ SEVK İŞLEMLERİ'!$A:$A,"05.02*") -> 0 | K7: =COUNTIFS('05 TAKDİRİ SEVK İŞLEMLERİ'!$B:$B,$A7,'05 TAKDİRİ SEVK İŞLEMLERİ'!$A:$A,"05.03*") -> 3 | L7: =COUNTIFS('05 TAKDİRİ SEVK İŞLEMLERİ'!$B:$B,$A7,'05 TAKDİRİ SEVK İŞLEMLERİ'!$A:$A,"05.04*") -> 0 | M7: =COUNTIFS('05 TAKDİRİ SEVK İŞLEMLERİ'!$B:$B,$A7,'05 TAKDİRİ SEVK İŞLEMLERİ'!$A:$A,"05.05*") -> 0 | N7: =COUNTIFS('06 VERGİ CEZA İHBARNAMELERİ'!$B:$B,$A7,'06 VERGİ CEZA İHBARNAMELERİ'!$A:$A,"06.01*") -> 0 | O7: =COUNTIFS('06 VERGİ CEZA İHBARNAMELERİ'!$B:$B,$A7,'06 VERGİ CEZA İHBARNAMELERİ'!$A:$A,"06.02*") -> 47 | P7: =COUNTIFS('06 VERGİ CEZA İHBARNAMELERİ'!$B:$B,$A7,'06 VERGİ CEZA İHBARNAMELERİ'!$A:$A,"06.03*") -> 1 | Q7: =COUNTIFS('06 VERGİ CEZA İHBARNAMELERİ'!$B:$B,$A7,'06 VERGİ CEZA İHBARNAMELERİ'!$A:$A,"06.04*") -> 6 | R7: =COUNTIFS('06 VERGİ CEZA İHBARNAMELERİ'!$B:$B,$A7,'06 VERGİ CEZA İHBARNAMELERİ'!$A:$A,"06.05*") -> 2 | S7: =COUNTIFS('08 SÜREKSİZ YÜKÜMLÜLÜKLER'!$B:$B,$A7,'08 SÜREKSİZ YÜKÜMLÜLÜKLER'!$A:$A,"08.04*") -> 0 | T7: =COUNTIFS('09 KANUNİ SÜRESİNDEN SONRA VERİ'!$B:$B,$A7,'09 KANUNİ SÜRESİNDEN SONRA VERİ'!$A:$A,"09.01*") -> 0 | U7: =COUNTIFS('09 KANUNİ SÜRESİNDEN SONRA VERİ'!$B:$B,$A7,'09 KANUNİ SÜRESİNDEN SONRA VERİ'!$A:$A,"09.02*") -> 0 | V7: =COUNTIFS('09 KANUNİ SÜRESİNDEN SONRA VERİ'!$B:$B,$A7,'09 KANUNİ SÜRESİNDEN SONRA VERİ'!$A:$A,"09.03*") -> 1 | W7: =COUNTIFS('09 KANUNİ SÜRESİNDEN SONRA VERİ'!$B:$B,$A7,'09 KANUNİ SÜRESİNDEN SONRA VERİ'!$A:$A,"09.04*") -> 4 | X7: =COUNTIFS('09 KANUNİ SÜRESİNDEN SONRA VERİ'!$B:$B,$A7,'09 KANUNİ SÜRESİNDEN SONRA VERİ'!$A:$A,"09.05*") -> 1 | Y7: =SUM(B7:X7) -> 65
A8: Ahmet TARANCI | B8: =COUNTIFS('03 VERGİ İNCELEME RAPORU'!$B:$B,$A8,'03 VERGİ İNCELEME RAPORU'!$A:$A,"03.01*") -> 0 | C8: =COUNTIFS('03 VERGİ İNCELEME RAPORU'!$B:$B,$A8,'03 VERGİ İNCELEME RAPORU'!$A:$A,"03.02*") -> 2 | D8: =COUNTIFS('03 VERGİ İNCELEME RAPORU'!$B:$B,$A8,'03 VERGİ İNCELEME RAPORU'!$A:$A,"03.03*") -> 0 | E8: =COUNTIFS('03 VERGİ İNCELEME RAPORU'!$B:$B,$A8,'03 VERGİ İNCELEME RAPORU'!$A:$A,"03.04*") -> 26 | F8: =COUNTIFS('03 VERGİ İNCELEME RAPORU'!$B:$B,$A8,'03 VERGİ İNCELEME RAPORU'!$A:$A,"03.05*") -> 23 | G8: =COUNTIFS('03 VERGİ İNCELEME RAPORU'!$B:$B,$A8,'03 VERGİ İNCELEME RAPORU'!$A:$A,"03.06*") -> 0 | H8: =COUNTIFS('03 VERGİ İNCELEME RAPORU'!$B:$B,$A8,'03 VERGİ İNCELEME RAPORU'!$A:$A,"03.08*") -> 0 | I8: =COUNTIFS('05 TAKDİRİ SEVK İŞLEMLERİ'!$B:$B,$A8,'05 TAKDİRİ SEVK İŞLEMLERİ'!$A:$A,"05.01*") -> 0 | J8: =COUNTIFS('05 TAKDİRİ SEVK İŞLEMLERİ'!$B:$B,$A8,'05 TAKDİRİ SEVK İŞLEMLERİ'!$A:$A,"05.02*") -> 1 | K8: =COUNTIFS('05 TAKDİRİ SEVK İŞLEMLERİ'!$B:$B,$A8,'05 TAKDİRİ SEVK İŞLEMLERİ'!$A:$A,"05.03*") -> 25 | L8: =COUNTIFS('05 TAKDİRİ SEVK İŞLEMLERİ'!$B:$B,$A8,'05 TAKDİRİ SEVK İŞLEMLERİ'!$A:$A,"05.04*") -> 0 | M8: =COUNTIFS('05 TAKDİRİ SEVK İŞLEMLERİ'!$B:$B,$A8,'05 TAKDİRİ SEVK İŞLEMLERİ'!$A:$A,"05.05*") -> 2 | N8: =COUNTIFS('06 VERGİ CEZA İHBARNAMELERİ'!$B:$B,$A8,'06 VERGİ CEZA İHBARNAMELERİ'!$A:$A,"06.01*") -> 1 | O8: =COUNTIFS('06 VERGİ CEZA İHBARNAMELERİ'!$B:$B,$A8,'06 VERGİ CEZA İHBARNAMELERİ'!$A:$A,"06.02*") -> 9 | P8: =COUNTIFS('06 VERGİ CEZA İHBARNAMELERİ'!$B:$B,$A8,'06 VERGİ CEZA İHBARNAMELERİ'!$A:$A,"06.03*") -> 8 | Q8: =COUNTIFS('06 VERGİ CEZA İHBARNAMELERİ'!$B:$B,$A8,'06 VERGİ CEZA İHBARNAMELERİ'!$A:$A,"06.04*") -> 1 | R8: =COUNTIFS('06 VERGİ CEZA İHBARNAMELERİ'!$B:$B,$A8,'06 VERGİ CEZA İHBARNAMELERİ'!$A:$A,"06.05*") -> 7 | S8: =COUNTIFS('08 SÜREKSİZ YÜKÜMLÜLÜKLER'!$B:$B,$A8,'08 SÜREKSİZ YÜKÜMLÜLÜKLER'!$A:$A,"08.04*") -> 0 | T8: =COUNTIFS('09 KANUNİ SÜRESİNDEN SONRA VERİ'!$B:$B,$A8,'09 KANUNİ SÜRESİNDEN SONRA VERİ'!$A:$A,"09.01*") -> 0 | U8: =COUNTIFS('09 KANUNİ SÜRESİNDEN SONRA VERİ'!$B:$B,$A8,'09 KANUNİ SÜRESİNDEN SONRA VERİ'!$A:$A,"09.02*") -> 0 | V8: =COUNTIFS('09 KANUNİ SÜRESİNDEN SONRA VERİ'!$B:$B,$A8,'09 KANUNİ SÜRESİNDEN SONRA VERİ'!$A:$A,"09.03*") -> 1 | W8: =COUNTIFS('09 KANUNİ SÜRESİNDEN SONRA VERİ'!$B:$B,$A8,'09 KANUNİ SÜRESİNDEN SONRA VERİ'!$A:$A,"09.04*") -> 1 | X8: =COUNTIFS('09 KANUNİ SÜRESİNDEN SONRA VERİ'!$B:$B,$A8,'09 KANUNİ SÜRESİNDEN SONRA VERİ'!$A:$A,"09.05*") -> 2 | Y8: =SUM(B8:X8) -> 109
A9: Resul MEYDAN | B9: =COUNTIFS('03 VERGİ İNCELEME RAPORU'!$B:$B,$A9,'03 VERGİ İNCELEME RAPORU'!$A:$A,"03.01*") -> 1 | C9: =COUNTIFS('03 VERGİ İNCELEME RAPORU'!$B:$B,$A9,'03 VERGİ İNCELEME RAPORU'!$A:$A,"03.02*") -> 0 | D9: =COUNTIFS('03 VERGİ İNCELEME RAPORU'!$B:$B,$A9,'03 VERGİ İNCELEME RAPORU'!$A:$A,"03.03*") -> 0 | E9: =COUNTIFS('03 VERGİ İNCELEME RAPORU'!$B:$B,$A9,'03 VERGİ İNCELEME RAPORU'!$A:$A,"03.04*") -> 0 | F9: =COUNTIFS('03 VERGİ İNCELEME RAPORU'!$B:$B,$A9,'03 VERGİ İNCELEME RAPORU'!$A:$A,"03.05*") -> 20 | G9: =COUNTIFS('03 VERGİ İNCELEME RAPORU'!$B:$B,$A9,'03 VERGİ İNCELEME RAPORU'!$A:$A,"03.06*") -> 0 | H9: =COUNTIFS('03 VERGİ İNCELEME RAPORU'!$B:$B,$A9,'03 VERGİ İNCELEME RAPORU'!$A:$A,"03.08*") -> 1 | I9: =COUNTIFS('05 TAKDİRİ SEVK İŞLEMLERİ'!$B:$B,$A9,'05 TAKDİRİ SEVK İŞLEMLERİ'!$A:$A,"05.01*") -> 0 | J9: =COUNTIFS('05 TAKDİRİ SEVK İŞLEMLERİ'!$B:$B,$A9,'05 TAKDİRİ SEVK İŞLEMLERİ'!$A:$A,"05.02*") -> 6 | K9: =COUNTIFS('05 TAKDİRİ SEVK İŞLEMLERİ'!$B:$B,$A9,'05 TAKDİRİ SEVK İŞLEMLERİ'!$A:$A,"05.03*") -> 12 | L9: =COUNTIFS('05 TAKDİRİ SEVK İŞLEMLERİ'!$B:$B,$A9,'05 TAKDİRİ SEVK İŞLEMLERİ'!$A:$A,"05.04*") -> 0 | M9: =COUNTIFS('05 TAKDİRİ SEVK İŞLEMLERİ'!$B:$B,$A9,'05 TAKDİRİ SEVK İŞLEMLERİ'!$A:$A,"05.05*") -> 1 | N9: =COUNTIFS('06 VERGİ CEZA İHBARNAMELERİ'!$B:$B,$A9,'06 VERGİ CEZA İHBARNAMELERİ'!$A:$A,"06.01*") -> 2 | O9: =COUNTIFS('06 VERGİ CEZA İHBARNAMELERİ'!$B:$B,$A9,'06 VERGİ CEZA İHBARNAMELERİ'!$A:$A,"06.02*") -> 2 | P9: =COUNTIFS('06 VERGİ CEZA İHBARNAMELERİ'!$B:$B,$A9,'06 VERGİ CEZA İHBARNAMELERİ'!$A:$A,"06.03*") -> 10 | Q9: =COUNTIFS('06 VERGİ CEZA İHBARNAMELERİ'!$B:$B,$A9,'06 VERGİ CEZA İHBARNAMELERİ'!$A:$A,"06.04*") -> 13 | R9: =COUNTIFS('06 VERGİ CEZA İHBARNAMELERİ'!$B:$B,$A9,'06 VERGİ CEZA İHBARNAMELERİ'!$A:$A,"06.05*") -> 2 | S9: =COUNTIFS('08 SÜREKSİZ YÜKÜMLÜLÜKLER'!$B:$B,$A9,'08 SÜREKSİZ YÜKÜMLÜLÜKLER'!$A:$A,"08.04*") -> 0 | T9: =COUNTIFS('09 KANUNİ SÜRESİNDEN SONRA VERİ'!$B:$B,$A9,'09 KANUNİ SÜRESİNDEN SONRA VERİ'!$A:$A,"09.01*") -> 1 | U9: =COUNTIFS('09 KANUNİ SÜRESİNDEN SONRA VERİ'!$B:$B,$A9,'09 KANUNİ SÜRESİNDEN SONRA VERİ'!$A:$A,"09.02*") -> 1 | V9: =COUNTIFS('09 KANUNİ SÜRESİNDEN SONRA VERİ'!$B:$B,$A9,'09 KANUNİ SÜRESİNDEN SONRA VERİ'!$A:$A,"09.03*") -> 0 | W9: =COUNTIFS('09 KANUNİ SÜRESİNDEN SONRA VERİ'!$B:$B,$A9,'09 KANUNİ SÜRESİNDEN SONRA VERİ'!$A:$A,"09.04*") -> 3 | X9: =COUNTIFS('09 KANUNİ SÜRESİNDEN SONRA VERİ'!$B:$B,$A9,'09 KANUNİ SÜRESİNDEN SONRA VERİ'!$A:$A,"09.05*") -> 2 | Y9: =SUM(B9:X9) -> 77
A10: Nuran KARAKAYA | B10: =COUNTIFS('03 VERGİ İNCELEME RAPORU'!$B:$B,$A10,'03 VERGİ İNCELEME RAPORU'!$A:$A,"03.01*") -> 0 | C10: =COUNTIFS('03 VERGİ İNCELEME RAPORU'!$B:$B,$A10,'03 VERGİ İNCELEME RAPORU'!$A:$A,"03.02*") -> 0 | D10: =COUNTIFS('03 VERGİ İNCELEME RAPORU'!$B:$B,$A10,'03 VERGİ İNCELEME RAPORU'!$A:$A,"03.03*") -> 0 | E10: =COUNTIFS('03 VERGİ İNCELEME RAPORU'!$B:$B,$A10,'03 VERGİ İNCELEME RAPORU'!$A:$A,"03.04*") -> 0 | F10: =COUNTIFS('03 VERGİ İNCELEME RAPORU'!$B:$B,$A10,'03 VERGİ İNCELEME RAPORU'!$A:$A,"03.05*") -> 9 | G10: =COUNTIFS('03 VERGİ İNCELEME RAPORU'!$B:$B,$A10,'03 VERGİ İNCELEME RAPORU'!$A:$A,"03.06*") -> 0 | H10: =COUNTIFS('03 VERGİ İNCELEME RAPORU'!$B:$B,$A10,'03 VERGİ İNCELEME RAPORU'!$A:$A,"03.08*") -> 0 | I10: =COUNTIFS('05 TAKDİRİ SEVK İŞLEMLERİ'!$B:$B,$A10,'05 TAKDİRİ SEVK İŞLEMLERİ'!$A:$A,"05.01*") -> 0 | J10: =COUNTIFS('05 TAKDİRİ SEVK İŞLEMLERİ'!$B:$B,$A10,'05 TAKDİRİ SEVK İŞLEMLERİ'!$A:$A,"05.02*") -> 6 | K10: =COUNTIFS('05 TAKDİRİ SEVK İŞLEMLERİ'!$B:$B,$A10,'05 TAKDİRİ SEVK İŞLEMLERİ'!$A:$A,"05.03*") -> 3 | L10: =COUNTIFS('05 TAKDİRİ SEVK İŞLEMLERİ'!$B:$B,$A10,'05 TAKDİRİ SEVK İŞLEMLERİ'!$A:$A,"05.04*") -> 0 | M10: =COUNTIFS('05 TAKDİRİ SEVK İŞLEMLERİ'!$B:$B,$A10,'05 TAKDİRİ SEVK İŞLEMLERİ'!$A:$A,"05.05*") -> 2 | N10: =COUNTIFS('06 VERGİ CEZA İHBARNAMELERİ'!$B:$B,$A10,'06 VERGİ CEZA İHBARNAMELERİ'!$A:$A,"06.01*") -> 1 | O10: =COUNTIFS('06 VERGİ CEZA İHBARNAMELERİ'!$B:$B,$A10,'06 VERGİ CEZA İHBARNAMELERİ'!$A:$A,"06.02*") -> 4 | P10: =COUNTIFS('06 VERGİ CEZA İHBARNAMELERİ'!$B:$B,$A10,'06 VERGİ CEZA İHBARNAMELERİ'!$A:$A,"06.03*") -> 35 | Q10: =COUNTIFS('06 VERGİ CEZA İHBARNAMELERİ'!$B:$B,$A10,'06 VERGİ CEZA İHBARNAMELERİ'!$A:$A,"06.04*") -> 3 | R10: =COUNTIFS('06 VERGİ CEZA İHBARNAMELERİ'!$B:$B,$A10,'06 VERGİ CEZA İHBARNAMELERİ'!$A:$A,"06.05*") -> 3 | S10: =COUNTIFS('08 SÜREKSİZ YÜKÜMLÜLÜKLER'!$B:$B,$A10,'08 SÜREKSİZ YÜKÜMLÜLÜKLER'!$A:$A,"08.04*") -> 0 | T10: =COUNTIFS('09 KANUNİ SÜRESİNDEN SONRA VERİ'!$B:$B,$A10,'09 KANUNİ SÜRESİNDEN SONRA VERİ'!$A:$A,"09.01*") -> 0 | U10: =COUNTIFS('09 KANUNİ SÜRESİNDEN SONRA VERİ'!$B:$B,$A10,'09 KANUNİ SÜRESİNDEN SONRA VERİ'!$A:$A,"09.02*") -> 3 | V10: =COUNTIFS('09 KANUNİ SÜRESİNDEN SONRA VERİ'!$B:$B,$A10,'09 KANUNİ SÜRESİNDEN SONRA VERİ'!$A:$A,"09.03*") -> 0 | W10: =COUNTIFS('09 KANUNİ SÜRESİNDEN SONRA VERİ'!$B:$B,$A10,'09 KANUNİ SÜRESİNDEN SONRA VERİ'!$A:$A,"09.04*") -> 4 | X10: =COUNTIFS('09 KANUNİ SÜRESİNDEN SONRA VERİ'!$B:$B,$A10,'09 KANUNİ SÜRESİNDEN SONRA VERİ'!$A:$A,"09.05*") -> 0 | Y10: =SUM(B10:X10) -> 73
A11: Nur Berru YENİÇERİ | B11: =COUNTIFS('03 VERGİ İNCELEME RAPORU'!$B:$B,$A11,'03 VERGİ İNCELEME RAPORU'!$A:$A,"03.01*") -> 0 | C11: =COUNTIFS('03 VERGİ İNCELEME RAPORU'!$B:$B,$A11,'03 VERGİ İNCELEME RAPORU'!$A:$A,"03.02*") -> 0 | D11: =COUNTIFS('03 VERGİ İNCELEME RAPORU'!$B:$B,$A11,'03 VERGİ İNCELEME RAPORU'!$A:$A,"03.03*") -> 0 | E11: =COUNTIFS('03 VERGİ İNCELEME RAPORU'!$B:$B,$A11,'03 VERGİ İNCELEME RAPORU'!$A:$A,"03.04*") -> 0 | F11: =COUNTIFS('03 VERGİ İNCELEME RAPORU'!$B:$B,$A11,'03 VERGİ İNCELEME RAPORU'!$A:$A,"03.05*") -> 0 | G11: =COUNTIFS('03 VERGİ İNCELEME RAPORU'!$B:$B,$A11,'03 VERGİ İNCELEME RAPORU'!$A:$A,"03.06*") -> 0 | H11: =COUNTIFS('03 VERGİ İNCELEME RAPORU'!$B:$B,$A11,'03 VERGİ İNCELEME RAPORU'!$A:$A,"03.08*") -> 0 | I11: =COUNTIFS('05 TAKDİRİ SEVK İŞLEMLERİ'!$B:$B,$A11,'05 TAKDİRİ SEVK İŞLEMLERİ'!$A:$A,"05.01*") -> 0 | J11: =COUNTIFS('05 TAKDİRİ SEVK İŞLEMLERİ'!$B:$B,$A11,'05 TAKDİRİ SEVK İŞLEMLERİ'!$A:$A,"05.02*") -> 1 | K11: =COUNTIFS('05 TAKDİRİ SEVK İŞLEMLERİ'!$B:$B,$A11,'05 TAKDİRİ SEVK İŞLEMLERİ'!$A:$A,"05.03*") -> 0 | L11: =COUNTIFS('05 TAKDİRİ SEVK İŞLEMLERİ'!$B:$B,$A11,'05 TAKDİRİ SEVK İŞLEMLERİ'!$A:$A,"05.04*") -> 0 | M11: =COUNTIFS('05 TAKDİRİ SEVK İŞLEMLERİ'!$B:$B,$A11,'05 TAKDİRİ SEVK İŞLEMLERİ'!$A:$A,"05.05*") -> 1 | N11: =COUNTIFS('06 VERGİ CEZA İHBARNAMELERİ'!$B:$B,$A11,'06 VERGİ CEZA İHBARNAMELERİ'!$A:$A,"06.01*") -> 0 | O11: =COUNTIFS('06 VERGİ CEZA İHBARNAMELERİ'!$B:$B,$A11,'06 VERGİ CEZA İHBARNAMELERİ'!$A:$A,"06.02*") -> 10 | P11: =COUNTIFS('06 VERGİ CEZA İHBARNAMELERİ'!$B:$B,$A11,'06 VERGİ CEZA İHBARNAMELERİ'!$A:$A,"06.03*") -> 17 | Q11: =COUNTIFS('06 VERGİ CEZA İHBARNAMELERİ'!$B:$B,$A11,'06 VERGİ CEZA İHBARNAMELERİ'!$A:$A,"06.04*") -> 0 | R11: =COUNTIFS('06 VERGİ CEZA İHBARNAMELERİ'!$B:$B,$A11,'06 VERGİ CEZA İHBARNAMELERİ'!$A:$A,"06.05*") -> 2 | S11: =COUNTIFS('08 SÜREKSİZ YÜKÜMLÜLÜKLER'!$B:$B,$A11,'08 SÜREKSİZ YÜKÜMLÜLÜKLER'!$A:$A,"08.04*") -> 0 | T11: =COUNTIFS('09 KANUNİ SÜRESİNDEN SONRA VERİ'!$B:$B,$A11,'09 KANUNİ SÜRESİNDEN SONRA VERİ'!$A:$A,"09.01*") -> 0 | U11: =COUNTIFS('09 KANUNİ SÜRESİNDEN SONRA VERİ'!$B:$B,$A11,'09 KANUNİ SÜRESİNDEN SONRA VERİ'!$A:$A,"09.02*") -> 0 | V11: =COUNTIFS('09 KANUNİ SÜRESİNDEN SONRA VERİ'!$B:$B,$A11,'09 KANUNİ SÜRESİNDEN SONRA VERİ'!$A:$A,"09.03*") -> 0 | W11: =COUNTIFS('09 KANUNİ SÜRESİNDEN SONRA VERİ'!$B:$B,$A11,'09 KANUNİ SÜRESİNDEN SONRA VERİ'!$A:$A,"09.04*") -> 2 | X11: =COUNTIFS('09 KANUNİ SÜRESİNDEN SONRA VERİ'!$B:$B,$A11,'09 KANUNİ SÜRESİNDEN SONRA VERİ'!$A:$A,"09.05*") -> 2 | Y11: =SUM(B11:X11) -> 35
A12: Canan YILDIZOĞLU | B12: =COUNTIFS('03 VERGİ İNCELEME RAPORU'!$B:$B,$A12,'03 VERGİ İNCELEME RAPORU'!$A:$A,"03.01*") -> 0 | C12: =COUNTIFS('03 VERGİ İNCELEME RAPORU'!$B:$B,$A12,'03 VERGİ İNCELEME RAPORU'!$A:$A,"03.02*") -> 0 | D12: =COUNTIFS('03 VERGİ İNCELEME RAPORU'!$B:$B,$A12,'03 VERGİ İNCELEME RAPORU'!$A:$A,"03.03*") -> 0 | E12: =COUNTIFS('03 VERGİ İNCELEME RAPORU'!$B:$B,$A12,'03 VERGİ İNCELEME RAPORU'!$A:$A,"03.04*") -> 0 | F12: =COUNTIFS('03 VERGİ İNCELEME RAPORU'!$B:$B,$A12,'03 VERGİ İNCELEME RAPORU'!$A:$A,"03.05*") -> 6 | G12: =COUNTIFS('03 VERGİ İNCELEME RAPORU'!$B:$B,$A12,'03 VERGİ İNCELEME RAPORU'!$A:$A,"03.06*") -> 0 | H12: =COUNTIFS('03 VERGİ İNCELEME RAPORU'!$B:$B,$A12,'03 VERGİ İNCELEME RAPORU'!$A:$A,"03.08*") -> 0 | I12: =COUNTIFS('05 TAKDİRİ SEVK İŞLEMLERİ'!$B:$B,$A12,'05 TAKDİRİ SEVK İŞLEMLERİ'!$A:$A,"05.01*") -> 0 | J12: =COUNTIFS('05 TAKDİRİ SEVK İŞLEMLERİ'!$B:$B,$A12,'05 TAKDİRİ SEVK İŞLEMLERİ'!$A:$A,"05.02*") -> 1 | K12: =COUNTIFS('05 TAKDİRİ SEVK İŞLEMLERİ'!$B:$B,$A12,'05 TAKDİRİ SEVK İŞLEMLERİ'!$A:$A,"05.03*") -> 0 | L12: =COUNTIFS('05 TAKDİRİ SEVK İŞLEMLERİ'!$B:$B,$A12,'05 TAKDİRİ SEVK İŞLEMLERİ'!$A:$A,"05.04*") -> 0 | M12: =COUNTIFS('05 TAKDİRİ SEVK İŞLEMLERİ'!$B:$B,$A12,'05 TAKDİRİ SEVK İŞLEMLERİ'!$A:$A,"05.05*") -> 1 | N12: =COUNTIFS('06 VERGİ CEZA İHBARNAMELERİ'!$B:$B,$A12,'06 VERGİ CEZA İHBARNAMELERİ'!$A:$A,"06.01*") -> 1 | O12: =COUNTIFS('06 VERGİ CEZA İHBARNAMELERİ'!$B:$B,$A12,'06 VERGİ CEZA İHBARNAMELERİ'!$A:$A,"06.02*") -> 6 | P12: =COUNTIFS('06 VERGİ CEZA İHBARNAMELERİ'!$B:$B,$A12,'06 VERGİ CEZA İHBARNAMELERİ'!$A:$A,"06.03*") -> 2 | Q12: =COUNTIFS('06 VERGİ CEZA İHBARNAMELERİ'!$B:$B,$A12,'06 VERGİ CEZA İHBARNAMELERİ'!$A:$A,"06.04*") -> 14 | R12: =COUNTIFS('06 VERGİ CEZA İHBARNAMELERİ'!$B:$B,$A12,'06 VERGİ CEZA İHBARNAMELERİ'!$A:$A,"06.05*") -> 6 | S12: =COUNTIFS('08 SÜREKSİZ YÜKÜMLÜLÜKLER'!$B:$B,$A12,'08 SÜREKSİZ YÜKÜMLÜLÜKLER'!$A:$A,"08.04*") -> 5 | T12: =COUNTIFS('09 KANUNİ SÜRESİNDEN SONRA VERİ'!$B:$B,$A12,'09 KANUNİ SÜRESİNDEN SONRA VERİ'!$A:$A,"09.01*") -> 0 | U12: =COUNTIFS('09 KANUNİ SÜRESİNDEN SONRA VERİ'!$B:$B,$A12,'09 KANUNİ SÜRESİNDEN SONRA VERİ'!$A:$A,"09.02*") -> 0 | V12: =COUNTIFS('09 KANUNİ SÜRESİNDEN SONRA VERİ'!$B:$B,$A12,'09 KANUNİ SÜRESİNDEN SONRA VERİ'!$A:$A,"09.03*") -> 0 | W12: =COUNTIFS('09 KANUNİ SÜRESİNDEN SONRA VERİ'!$B:$B,$A12,'09 KANUNİ SÜRESİNDEN SONRA VERİ'!$A:$A,"09.04*") -> 2 | X12: =COUNTIFS('09 KANUNİ SÜRESİNDEN SONRA VERİ'!$B:$B,$A12,'09 KANUNİ SÜRESİNDEN SONRA VERİ'!$A:$A,"09.05*") -> 3 | Y12: =SUM(B12:X12) -> 47
A13: Ali BEŞTAŞ | B13: =COUNTIFS('03 VERGİ İNCELEME RAPORU'!$B:$B,$A13,'03 VERGİ İNCELEME RAPORU'!$A:$A,"03.01*") -> 0 | C13: =COUNTIFS('03 VERGİ İNCELEME RAPORU'!$B:$B,$A13,'03 VERGİ İNCELEME RAPORU'!$A:$A,"03.02*") -> 0 | D13: =COUNTIFS('03 VERGİ İNCELEME RAPORU'!$B:$B,$A13,'03 VERGİ İNCELEME RAPORU'!$A:$A,"03.03*") -> 0 | E13: =COUNTIFS('03 VERGİ İNCELEME RAPORU'!$B:$B,$A13,'03 VERGİ İNCELEME RAPORU'!$A:$A,"03.04*") -> 1 | F13: =COUNTIFS('03 VERGİ İNCELEME RAPORU'!$B:$B,$A13,'03 VERGİ İNCELEME RAPORU'!$A:$A,"03.05*") -> 2 | G13: =COUNTIFS('03 VERGİ İNCELEME RAPORU'!$B:$B,$A13,'03 VERGİ İNCELEME RAPORU'!$A:$A,"03.06*") -> 0 | H13: =COUNTIFS('03 VERGİ İNCELEME RAPORU'!$B:$B,$A13,'03 VERGİ İNCELEME RAPORU'!$A:$A,"03.08*") -> 0 | I13: =COUNTIFS('05 TAKDİRİ SEVK İŞLEMLERİ'!$B:$B,$A13,'05 TAKDİRİ SEVK İŞLEMLERİ'!$A:$A,"05.01*") -> 0 | J13: =COUNTIFS('05 TAKDİRİ SEVK İŞLEMLERİ'!$B:$B,$A13,'05 TAKDİRİ SEVK İŞLEMLERİ'!$A:$A,"05.02*") -> 3 | K13: =COUNTIFS('05 TAKDİRİ SEVK İŞLEMLERİ'!$B:$B,$A13,'05 TAKDİRİ SEVK İŞLEMLERİ'!$A:$A,"05.03*") -> 12 | L13: =COUNTIFS('05 TAKDİRİ SEVK İŞLEMLERİ'!$B:$B,$A13,'05 TAKDİRİ SEVK İŞLEMLERİ'!$A:$A,"05.04*") -> 11 | M13: =COUNTIFS('05 TAKDİRİ SEVK İŞLEMLERİ'!$B:$B,$A13,'05 TAKDİRİ SEVK İŞLEMLERİ'!$A:$A,"05.05*") -> 0 | N13: =COUNTIFS('06 VERGİ CEZA İHBARNAMELERİ'!$B:$B,$A13,'06 VERGİ CEZA İHBARNAMELERİ'!$A:$A,"06.01*") -> 115 | O13: =COUNTIFS('06 VERGİ CEZA İHBARNAMELERİ'!$B:$B,$A13,'06 VERGİ CEZA İHBARNAMELERİ'!$A:$A,"06.02*") -> 11 | P13: =COUNTIFS('06 VERGİ CEZA İHBARNAMELERİ'!$B:$B,$A13,'06 VERGİ CEZA İHBARNAMELERİ'!$A:$A,"06.03*") -> 0 | Q13: =COUNTIFS('06 VERGİ CEZA İHBARNAMELERİ'!$B:$B,$A13,'06 VERGİ CEZA İHBARNAMELERİ'!$A:$A,"06.04*") -> 31 | R13: =COUNTIFS('06 VERGİ CEZA İHBARNAMELERİ'!$B:$B,$A13,'06 VERGİ CEZA İHBARNAMELERİ'!$A:$A,"06.05*") -> 2 | S13: =COUNTIFS('08 SÜREKSİZ YÜKÜMLÜLÜKLER'!$B:$B,$A13,'08 SÜREKSİZ YÜKÜMLÜLÜKLER'!$A:$A,"08.04*") -> 0 | T13: =COUNTIFS('09 KANUNİ SÜRESİNDEN SONRA VERİ'!$B:$B,$A13,'09 KANUNİ SÜRESİNDEN SONRA VERİ'!$A:$A,"09.01*") -> 0 | U13: =COUNTIFS('09 KANUNİ SÜRESİNDEN SONRA VERİ'!$B:$B,$A13,'09 KANUNİ SÜRESİNDEN SONRA VERİ'!$A:$A,"09.02*") -> 0 | V13: =COUNTIFS('09 KANUNİ SÜRESİNDEN SONRA VERİ'!$B:$B,$A13,'09 KANUNİ SÜRESİNDEN SONRA VERİ'!$A:$A,"09.03*") -> 0 | W13: =COUNTIFS('09 KANUNİ SÜRESİNDEN SONRA VERİ'!$B:$B,$A13,'09 KANUNİ SÜRESİNDEN SONRA VERİ'!$A:$A,"09.04*") -> 0 | X13: =COUNTIFS('09 KANUNİ SÜRESİNDEN SONRA VERİ'!$B:$B,$A13,'09 KANUNİ SÜRESİNDEN SONRA VERİ'!$A:$A,"09.05*") -> 1 | Y13: =SUM(B13:X13) -> 189
A14: Hikmet ŞAHİN | B14: =COUNTIFS('03 VERGİ İNCELEME RAPORU'!$B:$B,$A14,'03 VERGİ İNCELEME RAPORU'!$A:$A,"03.01*") -> 1 | C14: =COUNTIFS('03 VERGİ İNCELEME RAPORU'!$B:$B,$A14,'03 VERGİ İNCELEME RAPORU'!$A:$A,"03.02*") -> 0 | D14: =COUNTIFS('03 VERGİ İNCELEME RAPORU'!$B:$B,$A14,'03 VERGİ İNCELEME RAPORU'!$A:$A,"03.03*") -> 0 | E14: =COUNTIFS('03 VERGİ İNCELEME RAPORU'!$B:$B,$A14,'03 VERGİ İNCELEME RAPORU'!$A:$A,"03.04*") -> 0 | F14: =COUNTIFS('03 VERGİ İNCELEME RAPORU'!$B:$B,$A14,'03 VERGİ İNCELEME RAPORU'!$A:$A,"03.05*") -> 10 | G14: =COUNTIFS('03 VERGİ İNCELEME RAPORU'!$B:$B,$A14,'03 VERGİ İNCELEME RAPORU'!$A:$A,"03.06*") -> 1 | H14: =COUNTIFS('03 VERGİ İNCELEME RAPORU'!$B:$B,$A14,'03 VERGİ İNCELEME RAPORU'!$A:$A,"03.08*") -> 0 | I14: =COUNTIFS('05 TAKDİRİ SEVK İŞLEMLERİ'!$B:$B,$A14,'05 TAKDİRİ SEVK İŞLEMLERİ'!$A:$A,"05.01*") -> 1 | J14: =COUNTIFS('05 TAKDİRİ SEVK İŞLEMLERİ'!$B:$B,$A14,'05 TAKDİRİ SEVK İŞLEMLERİ'!$A:$A,"05.02*") -> 1 | K14: =COUNTIFS('05 TAKDİRİ SEVK İŞLEMLERİ'!$B:$B,$A14,'05 TAKDİRİ SEVK İŞLEMLERİ'!$A:$A,"05.03*") -> 4 | L14: =COUNTIFS('05 TAKDİRİ SEVK İŞLEMLERİ'!$B:$B,$A14,'05 TAKDİRİ SEVK İŞLEMLERİ'!$A:$A,"05.04*") -> 3 | M14: =COUNTIFS('05 TAKDİRİ SEVK İŞLEMLERİ'!$B:$B,$A14,'05 TAKDİRİ SEVK İŞLEMLERİ'!$A:$A,"05.05*") -> 0 | N14: =COUNTIFS('06 VERGİ CEZA İHBARNAMELERİ'!$B:$B,$A14,'06 VERGİ CEZA İHBARNAMELERİ'!$A:$A,"06.01*") -> 5 | O14: =COUNTIFS('06 VERGİ CEZA İHBARNAMELERİ'!$B:$B,$A14,'06 VERGİ CEZA İHBARNAMELERİ'!$A:$A,"06.02*") -> 14 | P14: =COUNTIFS('06 VERGİ CEZA İHBARNAMELERİ'!$B:$B,$A14,'06 VERGİ CEZA İHBARNAMELERİ'!$A:$A,"06.03*") -> 5 | Q14: =COUNTIFS('06 VERGİ CEZA İHBARNAMELERİ'!$B:$B,$A14,'06 VERGİ CEZA İHBARNAMELERİ'!$A:$A,"06.04*") -> 47 | R14: =COUNTIFS('06 VERGİ CEZA İHBARNAMELERİ'!$B:$B,$A14,'06 VERGİ CEZA İHBARNAMELERİ'!$A:$A,"06.05*") -> 2 | S14: =COUNTIFS('08 SÜREKSİZ YÜKÜMLÜLÜKLER'!$B:$B,$A14,'08 SÜREKSİZ YÜKÜMLÜLÜKLER'!$A:$A,"08.04*") -> 7 | T14: =COUNTIFS('09 KANUNİ SÜRESİNDEN SONRA VERİ'!$B:$B,$A14,'09 KANUNİ SÜRESİNDEN SONRA VERİ'!$A:$A,"09.01*") -> 3 | U14: =COUNTIFS('09 KANUNİ SÜRESİNDEN SONRA VERİ'!$B:$B,$A14,'09 KANUNİ SÜRESİNDEN SONRA VERİ'!$A:$A,"09.02*") -> 3 | V14: =COUNTIFS('09 KANUNİ SÜRESİNDEN SONRA VERİ'!$B:$B,$A14,'09 KANUNİ SÜRESİNDEN SONRA VERİ'!$A:$A,"09.03*") -> 0 | W14: =COUNTIFS('09 KANUNİ SÜRESİNDEN SONRA VERİ'!$B:$B,$A14,'09 KANUNİ SÜRESİNDEN SONRA VERİ'!$A:$A,"09.04*") -> 2 | X14: =COUNTIFS('09 KANUNİ SÜRESİNDEN SONRA VERİ'!$B:$B,$A14,'09 KANUNİ SÜRESİNDEN SONRA VERİ'!$A:$A,"09.05*") -> 2 | Y14: =SUM(B14:X14) -> 111
A15: Ömer DÜNDAR | B15: =COUNTIFS('03 VERGİ İNCELEME RAPORU'!$B:$B,$A15,'03 VERGİ İNCELEME RAPORU'!$A:$A,"03.01*") -> 0 | C15: =COUNTIFS('03 VERGİ İNCELEME RAPORU'!$B:$B,$A15,'03 VERGİ İNCELEME RAPORU'!$A:$A,"03.02*") -> 0 | D15: =COUNTIFS('03 VERGİ İNCELEME RAPORU'!$B:$B,$A15,'03 VERGİ İNCELEME RAPORU'!$A:$A,"03.03*") -> 14 | E15: =COUNTIFS('03 VERGİ İNCELEME RAPORU'!$B:$B,$A15,'03 VERGİ İNCELEME RAPORU'!$A:$A,"03.04*") -> 0 | F15: =COUNTIFS('03 VERGİ İNCELEME RAPORU'!$B:$B,$A15,'03 VERGİ İNCELEME RAPORU'!$A:$A,"03.05*") -> 0 | G15: =COUNTIFS('03 VERGİ İNCELEME RAPORU'!$B:$B,$A15,'03 VERGİ İNCELEME RAPORU'!$A:$A,"03.06*") -> 0 | H15: =COUNTIFS('03 VERGİ İNCELEME RAPORU'!$B:$B,$A15,'03 VERGİ İNCELEME RAPORU'!$A:$A,"03.08*") -> 0 | I15: =COUNTIFS('05 TAKDİRİ SEVK İŞLEMLERİ'!$B:$B,$A15,'05 TAKDİRİ SEVK İŞLEMLERİ'!$A:$A,"05.01*") -> 3 | J15: =COUNTIFS('05 TAKDİRİ SEVK İŞLEMLERİ'!$B:$B,$A15,'05 TAKDİRİ SEVK İŞLEMLERİ'!$A:$A,"05.02*") -> 0 | K15: =COUNTIFS('05 TAKDİRİ SEVK İŞLEMLERİ'!$B:$B,$A15,'05 TAKDİRİ SEVK İŞLEMLERİ'!$A:$A,"05.03*") -> 1 | L15: =COUNTIFS('05 TAKDİRİ SEVK İŞLEMLERİ'!$B:$B,$A15,'05 TAKDİRİ SEVK İŞLEMLERİ'!$A:$A,"05.04*") -> 2 | M15: =COUNTIFS('05 TAKDİRİ SEVK İŞLEMLERİ'!$B:$B,$A15,'05 TAKDİRİ SEVK İŞLEMLERİ'!$A:$A,"05.05*") -> 0 | N15: =COUNTIFS('06 VERGİ CEZA İHBARNAMELERİ'!$B:$B,$A15,'06 VERGİ CEZA İHBARNAMELERİ'!$A:$A,"06.01*") -> 10 | O15: =COUNTIFS('06 VERGİ CEZA İHBARNAMELERİ'!$B:$B,$A15,'06 VERGİ CEZA İHBARNAMELERİ'!$A:$A,"06.02*") -> 20 | P15: =COUNTIFS('06 VERGİ CEZA İHBARNAMELERİ'!$B:$B,$A15,'06 VERGİ CEZA İHBARNAMELERİ'!$A:$A,"06.03*") -> 2 | Q15: =COUNTIFS('06 VERGİ CEZA İHBARNAMELERİ'!$B:$B,$A15,'06 VERGİ CEZA İHBARNAMELERİ'!$A:$A,"06.04*") -> 14 | R15: =COUNTIFS('06 VERGİ CEZA İHBARNAMELERİ'!$B:$B,$A15,'06 VERGİ CEZA İHBARNAMELERİ'!$A:$A,"06.05*") -> 4 | S15: =COUNTIFS('08 SÜREKSİZ YÜKÜMLÜLÜKLER'!$B:$B,$A15,'08 SÜREKSİZ YÜKÜMLÜLÜKLER'!$A:$A,"08.04*") -> 7 | T15: =COUNTIFS('09 KANUNİ SÜRESİNDEN SONRA VERİ'!$B:$B,$A15,'09 KANUNİ SÜRESİNDEN SONRA VERİ'!$A:$A,"09.01*") -> 0 | U15: =COUNTIFS('09 KANUNİ SÜRESİNDEN SONRA VERİ'!$B:$B,$A15,'09 KANUNİ SÜRESİNDEN SONRA VERİ'!$A:$A,"09.02*") -> 0 | V15: =COUNTIFS('09 KANUNİ SÜRESİNDEN SONRA VERİ'!$B:$B,$A15,'09 KANUNİ SÜRESİNDEN SONRA VERİ'!$A:$A,"09.03*") -> 0 | W15: =COUNTIFS('09 KANUNİ SÜRESİNDEN SONRA VERİ'!$B:$B,$A15,'09 KANUNİ SÜRESİNDEN SONRA VERİ'!$A:$A,"09.04*") -> 2 | X15: =COUNTIFS('09 KANUNİ SÜRESİNDEN SONRA VERİ'!$B:$B,$A15,'09 KANUNİ SÜRESİNDEN SONRA VERİ'!$A:$A,"09.05*") -> 3 | Y15: =SUM(B15:X15) -> 82
... A17: ARALIK DIŞI | B17: =COUNTIFS('03 VERGİ İNCELEME RAPORU'!$B:$B,$A17,'03 VERGİ İNCELEME RAPORU'!$A:$A,"03.01*") -> 0 | C17: =COUNTIFS('03 VERGİ İNCELEME RAPORU'!$B:$B,$A17,'03 VERGİ İNCELEME RAPORU'!$A:$A,"03.02*") -> 0 | D17: =COUNTIFS('03 VERGİ İNCELEME RAPORU'!$B:$B,$A17,'03 VERGİ İNCELEME RAPORU'!$A:$A,"03.03*") -> 0 | E17: =COUNTIFS('03 VERGİ İNCELEME RAPORU'!$B:$B,$A17,'03 VERGİ İNCELEME RAPORU'!$A:$A,"03.04*") -> 0 | F17: =COUNTIFS('03 VERGİ İNCELEME RAPORU'!$B:$B,$A17,'03 VERGİ İNCELEME RAPORU'!$A:$A,"03.05*") -> 0 | G17: =COUNTIFS('03 VERGİ İNCELEME RAPORU'!$B:$B,$A17,'03 VERGİ İNCELEME RAPORU'!$A:$A,"03.06*") -> 0 | H17: =COUNTIFS('03 VERGİ İNCELEME RAPORU'!$B:$B,$A17,'03 VERGİ İNCELEME RAPORU'!$A:$A,"03.08*") -> 0 | I17: =COUNTIFS('05 TAKDİRİ SEVK İŞLEMLERİ'!$B:$B,$A17,'05 TAKDİRİ SEVK İŞLEMLERİ'!$A:$A,"05.01*") -> 0 | J17: =COUNTIFS('05 TAKDİRİ SEVK İŞLEMLERİ'!$B:$B,$A17,'05 TAKDİRİ SEVK İŞLEMLERİ'!$A:$A,"05.02*") -> 0 | K17: =COUNTIFS('05 TAKDİRİ SEVK İŞLEMLERİ'!$B:$B,$A17,'05 TAKDİRİ SEVK İŞLEMLERİ'!$A:$A,"05.03*") -> 0 | L17: =COUNTIFS('05 TAKDİRİ SEVK İŞLEMLERİ'!$B:$B,$A17,'05 TAKDİRİ SEVK İŞLEMLERİ'!$A:$A,"05.04*") -> 0 | M17: =COUNTIFS('05 TAKDİRİ SEVK İŞLEMLERİ'!$B:$B,$A17,'05 TAKDİRİ SEVK İŞLEMLERİ'!$A:$A,"05.05*") -> 0 | N17: =COUNTIFS('06 VERGİ CEZA İHBARNAMELERİ'!$B:$B,$A17,'06 VERGİ CEZA İHBARNAMELERİ'!$A:$A,"06.01*") -> 0 | O17: =COUNTIFS('06 VERGİ CEZA İHBARNAMELERİ'!$B:$B,$A17,'06 VERGİ CEZA İHBARNAMELERİ'!$A:$A,"06.02*") -> 0 | P17: =COUNTIFS('06 VERGİ CEZA İHBARNAMELERİ'!$B:$B,$A17,'06 VERGİ CEZA İHBARNAMELERİ'!$A:$A,"06.03*") -> 0 | Q17: =COUNTIFS('06 VERGİ CEZA İHBARNAMELERİ'!$B:$B,$A17,'06 VERGİ CEZA İHBARNAMELERİ'!$A:$A,"06.04*") -> 0 | R17: =COUNTIFS('06 VERGİ CEZA İHBARNAMELERİ'!$B:$B,$A17,'06 VERGİ CEZA İHBARNAMELERİ'!$A:$A,"06.05*") -> 0 | S17: =COUNTIFS('08 SÜREKSİZ YÜKÜMLÜLÜKLER'!$B:$B,$A17,'08 SÜREKSİZ YÜKÜMLÜLÜKLER'!$A:$A,"08.04*") -> 0 | T17: =COUNTIFS('09 KANUNİ SÜRESİNDEN SONRA VERİ'!$B:$B,$A17,'09 KANUNİ SÜRESİNDEN SONRA VERİ'!$A:$A,"09.01*") -> 0 | U17: =COUNTIFS('09 KANUNİ SÜRESİNDEN SONRA VERİ'!$B:$B,$A17,'09 KANUNİ SÜRESİNDEN SONRA VERİ'!$A:$A,"09.02*") -> 0 | V17: =COUNTIFS('09 KANUNİ SÜRESİNDEN SONRA VERİ'!$B:$B,$A17,'09 KANUNİ SÜRESİNDEN SONRA VERİ'!$A:$A,"09.03*") -> 0 | W17: =COUNTIFS('09 KANUNİ SÜRESİNDEN SONRA VERİ'!$B:$B,$A17,'09 KANUNİ SÜRESİNDEN SONRA VERİ'!$A:$A,"09.04*") -> 0 | X17: =COUNTIFS('09 KANUNİ SÜRESİNDEN SONRA VERİ'!$B:$B,$A17,'09 KANUNİ SÜRESİNDEN SONRA VERİ'!$A:$A,"09.05*") -> 0 | Y17: =SUM(B17:X17) -> 0
A18: TOPLAM | B18: =SUM(B4:B17) -> 4 | C18: =SUM(C4:C17) -> 2 | D18: =SUM(D4:D17) -> 30 | E18: =SUM(E4:E17) -> 27 | F18: =SUM(F4:F17) -> 71 | G18: =SUM(G4:G17) -> 1 | H18: =SUM(H4:H17) -> 1 | I18: =SUM(I4:I17) -> 4 | ... Y18: =SUM(Y4:Y17) -> 997
A20: NOTLAR:
A21: • Aralıklar fotoğraftaki 'Vergilendirme' bölümü tablosundan alındı. Eşleşme sırayla ilk uyan aralığa göre yapıldı.
A22: • DİKKAT: Nuran KARAKAYA (4980000000–5959999999) ile Nur Berru YENİÇERİ (5360000000–6399999999) aralıkları 5360000000–5959999999 arasında ÇAKIŞIYOR; bu VKN'ler Nuran KARAKAYA'ya yazıldı. 5360 muhtemelen 5960 olmalı — araçta düzeltin.
A23: • Canan YILDIZOĞLU'nun bitişi 7333333333; 7333333334–7339999999 arası kimseye atanmamış (ARALIK DIŞI).
A24: • 'VKN YOK': satırda VKN alanı boş. Formüller COUNTIFS ile canlıdır; B sütunundaki sorumluyu elle değiştirirseniz özet güncellenir.

Sheet 03 VERGİ İNCELEME RAPORU
A1: AÇIKLAMA | B1: SORUMLU | C1: RAPOR KAYIT DEFTERİ NUMARASI | D1: İHBARNAME FİŞ NUMARASI | E1: RAPOR TARİHİ | F1: RAPOR SAYISI | G1: RAPOR TÜRÜ | H1: VERGİ KİMLİK NUMARASI | I1: UNVAN | J1: VERGİ KODU | K1: DÖNEM | L1: YAZI TARİHİ | M1: YAZI SAYISI | N1: VERGİ DAİRESİ KODU | O1: VERGİ DAİRESİ ADI | P1: İHBARNAME TARH EDİLEN TUTAR (USULSÜZLÜK) | Q1: RAPOR TARH ÖNERİLEN TUTAR (USULSÜZLÜK) | R1: USULSÜZLÜK FARK | S1: İHBARNAME TARH EDİLEN TUTAR (ÖZEL USULSÜZLÜK) | T1: RAPOR TARH ÖNERİLEN TUTAR(ÖZEL USULSÜZLÜK) | U1: ÖZEL USULSÜZLÜK FARK
A2: 03.08 - Vergi İnceleme Raporlarında Yer alan Usulsüzlük/Özel Usulsüzlük Tutarları ile İhbarnamelerde Yer Alan Usulsüzlük/Özel Usulsüzlük Tutarları Arasında Fark Olanlar Listesi | B2: Resul MEYDAN | C2: 2023081650QAF0000002 | D2: 2023090113QAE0000011 | E2: 02/08/2023 | F2: 2023-[2013-3-32]/14 | G2: VİR | H2: 4850713184 | I2: KACHOURA TEKSTİL KONFEKSİYON İTHALAT İHRACAT SANAYİİ VE TİCARET LİMİTED ŞİRKETİ | J2: 0015 | K2: 202112202112 | L2: 15/08/2023 | M2: 51781582-663.05[32603]-40188 | N2: 016252 | O2: YILDIRIM VERGİ DAİRESİ | P2: 240 | Q2: 240 | R2: 0 | T2: 9000 | U2: 9000
A5: AÇIKLAMA | B5: SORUMLU | C5: RAPOR KAYIT DEFTER NUMARASI | D5: VERGİ DAİRESİ KODU | E5: VERGİ DAİRESİ ADI | F5: VERGİ KİMLİK NUMARASI | G5: UNVAN | H5: VERGİ KODU | I5: DÖNEM | J5: RAPOR TARİHİ | K5: RAPOR SAYISI | L5: TOU DURUMU
A6: 03.02 - Rapor Kayıt Defterine Kaydedildiği Halde İhbarname Düzenlenmeyen Vergi İnceleme Raporları Listesi | B6: Ahmet TARANCI | C6: 2025051650QAE0000003 | D6: 016252 | E6: YILDIRIM VERGİ DAİRESİ | F6: 3341015383 | G6: EMS ÖRME KUMAŞ DOKUMA TEKSTİL SANAYİ VE TİCARET LİMİTED ŞİRKETİ | H6: 3080 | I6: 202105202105 | J6: 05/05/2025 | K6: 2025-[2014-3-703]/12 | L6: Yok
A7: 03.02 - Rapor Kayıt Defterine Kaydedildiği Halde İhbarname Düzenlenmeyen Vergi İnceleme Raporları Listesi | B7: Ahmet TARANCI | C7: 2025051650QAE0000003 | D7: 016252 | E7: YILDIRIM VERGİ DAİRESİ | F7: 3341015383 | G7: EMS ÖRME KUMAŞ DOKUMA TEKSTİL SANAYİ VE TİCARET LİMİTED ŞİRKETİ | H7: 3080 | I7: 202106202106 | J7: 05/05/2025 | K7: 2025-[2014-3-703]/12 | L7: Yok
A10: AÇIKLAMA | B10: SORUMLU | C10: İHBARNAME FİŞ NUMARASI | D10: İHBARNAME DÜZENLENME TARİHİ | E10: İHBARNAME DURUMU | F10: VERGİ DAİRESİ KODU | G10: VERGİ DAİRESİ ADI | H10: VERGİ KİMLİK NUMARASI | I10: UNVAN | J10: VERGİ KODU | K10: DÖNEM | L10: DAYANAK NUMARASI | M10: DAYANAK TÜRÜ AÇIKLAMASI
A11: 03.03 - Vergi İnceleme Raporlarına İstinaden Düzenlenen İhbarnamelerden Tarh Defterinde Geçici İhbarname Olarak Bekleyenlerin Listesi | B11: Ömer DÜNDAR | C11: 2026082613QAJ0000004 | D11: 26/08/2026 | E11: Geçici | F11: 016252 | G11: YILDIRIM VERGİ DAİRESİ | H11: 9390387080 | I11: AHMET YAŞA | J11: 0015 | K11: 202307202307 | L11: 2026082650QAK0000001 | M11: İnceleme Raporu
A12: 03.03 - Vergi İnceleme Raporlarına İstinaden Düzenlenen İhbarnamelerden Tarh Defterinde Geçici İhbarname Olarak Bekleyenlerin Listesi | B12: Ömer DÜNDAR | C12: 2026082613QAJ0000006 | D12: 26/08/2026 | E12: Geçici | F12: 016252 | G12: YILDIRIM VERGİ DAİRESİ | H12: 9390387080 | I12: AHMET YAŞA | J12: 0015 | K12: 202309202309 | L12: 2026082650QAK0000001 | M12: İnceleme Raporu
A13: 03.03 - Vergi İnceleme Raporlarına İstinaden Düzenlenen İhbarnamelerden Tarh Defterinde Geçici İhbarname Olarak Bekleyenlerin Listesi | B13: Ömer DÜNDAR | C13: 2026082613QAJ0000010 | D13: 26/08/2026 | E13: Geçici | F13: 016252 | G13: YILDIRIM VERGİ DAİRESİ | H13: 9390387080 | I13: AHMET YAŞA | J13: 0001 | K13: 202301202312 | L13: 2026082650QAK0000002 | M13: İnceleme Raporu
A14: 03.03 - Vergi İnceleme Raporlarına İstinaden Düzenlenen İhbarnamelerden Tarh Defterinde Geçici İhbarname Olarak Bekleyenlerin Listesi | B14: Ömer DÜNDAR | C14: 2026082613QAJ0000002 | D14: 26/08/2026 | E14: Geçici | F14: 016252 | G14: YILDIRIM VERGİ DAİRESİ | H14: 9390387080 | I14: AHMET YAŞA | J14: 0015 | K14: 202305202305 | L14: 2026082650QAK0000001 | M14: İnceleme Raporu
A15: 03.03 - Vergi İnceleme Raporlarına İstinaden Düzenlenen İhbarnamelerden Tarh Defterinde Geçici İhbarname Olarak Bekleyenlerin Listesi | B15: Ömer DÜNDAR | C15: 2026082613QAJ0000007 | D15: 26/08/2026 | E15: Geçici | F15: 016252 | G15: YILDIRIM VERGİ DAİRESİ | H15: 9390387080 | I15: AHMET YAŞA | J15: 0015 | K15: 202310202310 | L15: 2026082650QAK0000001 | M15: İnceleme Raporu
A16: 03.03 - Vergi İnceleme Raporlarına İstinaden Düzenlenen İhbarnamelerden Tarh Defterinde Geçici İhbarname Olarak Bekleyenlerin Listesi | B16: Ömer DÜNDAR | C16: 2026082613QAJ0000011 | D16: 26/08/2026 | E16: Geçici | F16: 016252 | G16: YILDIRIM VERGİ DAİRESİ | H16: 9390387080 | I16: AHMET YAŞA | J16: 0032 | K16: 202304202306 | L16: 2026082650QAK0000003 | M16: İnceleme Raporu
A17: 03.03 - Vergi İnceleme Raporlarına İstinaden Düzenlenen İhbarnamelerden Tarh Defterinde Geçici İhbarname Olarak Bekleyenlerin Listesi | B17: Ömer DÜNDAR | C17: 2026082613QAJ0000005 | D17: 26/08/2026 | E17: Geçici | F17: 016252 | G17: YILDIRIM VERGİ DAİRESİ | H17: 9390387080 | I17: AHMET YAŞA | J17: 0015 | K17: 202308202308 | L17: 2026082650QAK0000001 | M17: İnceleme Raporu
A18: 03.03 - Vergi İnceleme Raporlarına İstinaden Düzenlenen İhbarnamelerden Tarh Defterinde Geçici İhbarname Olarak Bekleyenlerin Listesi | B18: Ömer DÜNDAR | C18: 2026082613QAJ0000013 | D18: 26/08/2026 | E18: Geçici | F18: 016252 | G18: YILDIRIM VERGİ DAİRESİ | H18: 9390387080 | I18: AHMET YAŞA | J18: 0015 | K18: 202405202405 | L18: 2026082650QAK0000004 | M18: İnceleme Raporu
A19: 03.03 - Vergi İnceleme Raporlarına İstinaden Düzenlenen İhbarnamelerden Tarh Defterinde Geçici İhbarname Olarak Bekleyenlerin Listesi | B19: Ömer DÜNDAR | C19: 2026082613QAJ0000003 | D19: 26/08/2026 | E19: Geçici | F19: 016252 | G19: YILDIRIM VERGİ DAİRESİ | H19: 9390387080 | I19: AHMET YAŞA | J19: 0015 | K19: 202306202306 | L19: 2026082650QAK0000001 | M19: İnceleme Raporu
A20: 03.03 - Vergi İnceleme Raporlarına İstinaden Düzenlenen İhbarnamelerden Tarh Defterinde Geçici İhbarname Olarak Bekleyenlerin Listesi | B20: Ömer DÜNDAR | C20: 2026082613QAJ0000009 | D20: 26/08/2026 | E20: Geçici | F20: 016252 | G20: YILDIRIM VERGİ DAİRESİ | H20: 9390387080 | I20: AHMET YAŞA | J20: 0015 | K20: 202312202312 | L20: 2026082650QAK0000001 | M20: İnceleme Raporu
A21: 03.03 - Vergi İnceleme Raporlarına İstinaden Düzenlenen İhbarnamelerden Tarh Defterinde Geçici İhbarname Olarak Bekleyenlerin Listesi | B21: Ömer DÜNDAR | C21: 2026082613QAJ0000001 | D21: 26/08/2026 | E21: Geçici | F21: 016252 | G21: YILDIRIM VERGİ DAİRESİ | H21: 9390387080 | I21: AHMET YAŞA | J21: 0015 | K21: 202304202304 | L21: 2026082650QAK0000001 | M21: İnceleme Raporu
... A70: 03.04 - Vergi İnceleme Raporlarına İstinaden Düzenlenen İhbarnamelerden Tebliğ Edilmeyenlerin Listesi | B70: Ali BEŞTAŞ | C70: 2026081813QAH0000013 | D70: 18/08/2026 | E70: ONAYLANMIŞ | F70: 016252 | G70: YILDIRIM VERGİ DAİRESİ | H70: 7730699221 | I70: İFLAS HAL.SOLE KİDS TEKSTİL SANAYİ VE TİCARET LİMİTED ŞİRKETİ | J70: 0015 | K70: 202408202408 | L70: 2026081750QAI0000001 | M70: İnceleme Raporu
A73: AÇIKLAMA | B73: SORUMLU | C73: İHBARNAME FİŞ NUMARASI | D73: İHBARNAME DÜZENLENME TARİHİ | E73: İHBARNAME DURUMU | F73: TEBLİĞ TARİHİ | G73: VERGİ DAİRESİ KODU | H73: VERGİ DAİRESİ ADI | I73: VERGİ KİMLİK NUMARASI | J73: UNVAN | K73: VERGİ KODU | L73: DÖNEM
A74: 03.05 - Vergi İnceleme Raporlarına İstinaden Düzenlenmiş İhbarnamelerden Tebliğ Edilmesine Rağmen Tahakkuku Verilmeyenlerin Listesi | B74: Resul MEYDAN | C74: 2026070313QAE0000019 | D74: 03/07/2026 | E74: TEBLIĞ EDILMIŞ | F74: 12/07/2026 | G74: 016252 | H74: YILDIRIM VERGİ DAİRESİ | I74: 4621037507 | J74: HFK YÜZEY İŞLEM KİMYASALLARI TEKSTİL SANAYİ TİCARET LİMİTED ŞİRKETİ | K74: 0010 | L74: 202501202512
A75: 03.05 - Vergi İnceleme Raporlarına İstinaden Düzenlenmiş İhbarnamelerden Tebliğ Edilmesine Rağmen Tahakkuku Verilmeyenlerin Listesi | B75: Resul MEYDAN | C75: 2026070313QAE0000020 | D75: 03/07/2026 | E75: TEBLIĞ EDILMIŞ | F75: 12/07/2026 | G75: 016252 | H75: YILDIRIM VERGİ DAİRESİ | I75: 4621037507 | J75: HFK YÜZEY İŞLEM KİMYASALLARI TEKSTİL SANAYİ TİCARET LİMİTED ŞİRKETİ | K75: 0033 | L75: 202501202503
A76: 03.05 - Vergi İnceleme Raporlarına İstinaden Düzenlenmiş İhbarnamelerden Tebliğ Edilmesine Rağmen Tahakkuku Verilmeyenlerin Listesi | B76: Resul MEYDAN | C76: 2026070313QAE0000021 | D76: 03/07/2026 | E76: TEBLIĞ EDILMIŞ | F76: 12/07/2026 | G76: 016252 | H76: YILDIRIM VERGİ DAİRESİ | I76: 4621037507 | J76: HFK YÜZEY İŞLEM KİMYASALLARI TEKSTİL SANAYİ TİCARET LİMİTED ŞİRKETİ | K76: 0015 | L76: 202501202501
A77: 03.05 - Vergi İnceleme Raporlarına İstinaden Düzenlenmiş İhbarnamelerden Tebliğ Edilmesine Rağmen Tahakkuku Verilmeyenlerin Listesi | B77: Nuran KARAKAYA | C77: 2026041513QAF0000001 | D77: 15/04/2026 | E77: TEBLIĞ EDILMIŞ | F77: 20/05/2026 | G77: 016252 | H77: YILDIRIM VERGİ DAİRESİ | I77: 5341609401 | J77: ŞEVVAL KAYA | K77: 0015 | L77: 202409202409
A78: 03.05 - Vergi İnceleme Raporlarına İstinaden Düzenlenmiş İhbarnamelerden Tebliğ Edilmesine Rağmen Tahakkuku Verilmeyenlerin Listesi | B78: Nuran KARAKAYA | C78: 2026041513QAF0000002 | D78: 15/04/2026 | E78: TEBLIĞ EDILMIŞ | F78: 20/05/2026 | G78: 016252 | H78: YILDIRIM VERGİ DAİRESİ | I78: 5341609401 | J78: ŞEVVAL KAYA | K78: 0015 | L78: 202410202410
A79: 03.05 - Vergi İnceleme Raporlarına İstinaden Düzenlenmiş İhbarnamelerden Tebliğ Edilmesine Rağmen Tahakkuku Verilmeyenlerin Listesi | B79: Nuran KARAKAYA | C79: 2026041513QAF0000003 | D79: 15/04/2026 | E79: TEBLIĞ EDILMIŞ | F79: 20/05/2026 | G79: 016252 | H79: YILDIRIM VERGİ DAİRESİ | I79: 5341609401 | J79: ŞEVVAL KAYA | K79: 0015 | L79: 202411202411
A80: 03.05 - Vergi İnceleme Raporlarına İstinaden Düzenlenmiş İhbarnamelerden Tebliğ Edilmesine Rağmen Tahakkuku Verilmeyenlerin Listesi | B80: Nuran KARAKAYA | C80: 2026041513QAF0000004 | D80: 15/04/2026 | E80: TEBLIĞ EDILMIŞ | F80: 20/05/2026 | G80: 016252 | H80: YILDIRIM VERGİ DAİRESİ | I80: 5341609401 | J80: ŞEVVAL KAYA | K80: 0015 | L80: 202412202412
A81: 03.05 - Vergi İnceleme Raporlarına İstinaden Düzenlenmiş İhbarnamelerden Tebliğ Edilmesine Rağmen Tahakkuku Verilmeyenlerin Listesi | B81: Nuran KARAKAYA | C81: 2026041513QAF0000005 | D81: 15/04/2026 | E81: TEBLIĞ EDILMIŞ | F81: 20/05/2026 | G81: 016252 | H81: YILDIRIM VERGİ DAİRESİ | I81: 5341609401 | J81: ŞEVVAL KAYA | K81: 0015 | L81: 202507202507
A82: 03.05 - Vergi İnceleme Raporlarına İstinaden Düzenlenmiş İhbarnamelerden Tebliğ Edilmesine Rağmen Tahakkuku Verilmeyenlerin Listesi | B82: Nuran KARAKAYA | C82: 2026041513QAF0000006 | D82: 15/04/2026 | E82: TEBLIĞ EDILMIŞ | F82: 20/05/2026 | G82: 016252 | H82: YILDIRIM VERGİ DAİRESİ | I82: 5341609401 | J82: ŞEVVAL KAYA | K82: 0015 | L82: 202508202508
A83: 03.05 - Vergi İnceleme Raporlarına İstinaden Düzenlenmiş İhbarnamelerden Tebliğ Edilmesine Rağmen Tahakkuku Verilmeyenlerin Listesi | B83: Nuran KARAKAYA | C83: 2026041513QAF0000007 | D83: 15/04/2026 | E83: TEBLIĞ EDILMIŞ | F83: 20/05/2026 | G83: 016252 | H83: YILDIRIM VERGİ DAİRESİ | I83: 5341609401 | J83: ŞEVVAL KAYA | K83: 0015 | L83: 202509202509
A84: 03.05 - Vergi İnceleme Raporlarına İstinaden Düzenlenmiş İhbarnamelerden Tebliğ Edilmesine Rağmen Tahakkuku Verilmeyenlerin Listesi | B84: Nuran KARAKAYA | C84: 2026041513QAF0000008 | D84: 15/04/2026 | E84: TEBLIĞ EDILMIŞ | F84: 20/05/2026 | G84: 016252 | H84: YILDIRIM VERGİ DAİRESİ | I84: 5341609401 | J84: ŞEVVAL KAYA | K84: 0015 | L84: 202510202510
... A144: 03.05 - Vergi İnceleme Raporlarına İstinaden Düzenlenmiş İhbarnamelerden Tebliğ Edilmesine Rağmen Tahakkuku Verilmeyenlerin Listesi | B144: Resul MEYDAN | C144: 2026070313QAE0000018 | D144: 03/07/2026 | E144: TEBLIĞ EDILMIŞ | F144: 12/07/2026 | G144: 016252 | H144: YILDIRIM VERGİ DAİRESİ | I144: 4621037507 | J144: HFK YÜZEY İŞLEM KİMYASALLARI TEKSTİL SANAYİ TİCARET LİMİTED ŞİRKETİ | K144: 0015 | L144: 202412202412
A147: AÇIKLAMA | B147: SORUMLU | C147: RAPOR SAYISI | D147: RAPOR TARİHİ | E147: RAPOR TÜRÜ | F147: VERGİ KİMLİK NUMARASI | G147: UNVAN | H147: VERGİ KODU | I147: DÖNEM | J147: YAZI TARİHİ | K147: YAZI SAYISI | L147: VERGİ DAİRESİ KODU | M147: VERGİ DAİRESİ ADI
A148: 03.01 - Vergi Dairesine Gelen Vergi İnceleme Raporlarından Rapor Kayıt Defterine Kayıt Edilmeyenlerin Listesi | B148: Halim YARAR | C148: 2026-[2014-1-392]/47 | D148: 05/06/2026 | E148: VSR | F148: 2051210593 | G148: CEMRESU TEKSTİL SANAYİ VE TİCARET LİMİTED ŞİRKETİ | I148: 2023,2024 | J148: 30/07/2026 | K148: 51781582-663.05[48569]-50717 | L148: 016252 | M148: YILDIRIM VERGİ DAİRESİ
A149: 03.01 - Vergi Dairesine Gelen Vergi İnceleme Raporlarından Rapor Kayıt Defterine Kayıt Edilmeyenlerin Listesi | B149: Resul MEYDAN | C149: 2026-[1997-1-9]/26 | D149: 11/08/2026 | E149: VTR-Genel | F149: 4610800700 | G149: ADİL HELVANİ | I149: 2022 | J149: 26/08/2026 | K149: 51781582-663.05[55127]-56267 | L149: 016252 | M149: YILDIRIM VERGİ DAİRESİ
A150: 03.01 - Vergi Dairesine Gelen Vergi İnceleme Raporlarından Rapor Kayıt Defterine Kayıt Edilmeyenlerin Listesi | B150: Hikmet ŞAHİN | C150: 2026-[2014-3-182]/10 | D150: 09/07/2026 | E150: VTR-Kısmen Sahte Belge Düzenleme | F150: 8940386590 | G150: USL DIŞ TİCARET ANONİM ŞİRKETİ | I150: 2021,2022 | J150: 30/07/2026 | K150: 51781582-663.05[13287]-50700 | L150: 016252 | M150: YILDIRIM VERGİ DAİRESİ
A151: 03.01 - Vergi Dairesine Gelen Vergi İnceleme Raporlarından Rapor Kayıt Defterine Kayıt Edilmeyenlerin Listesi | B151: Nalan ŞERİF | C151: 2026-[2014-3-182]/15 | D151: 14/07/2026 | E151: VİR | F151: 0691192117 | G151: ANALIZ GROUP METAL ÇELIK SANAYI VE TICARET LIMITED SIRKETI | H151: 0015 | I151: 2021/04,05,06,07,08,09,10,11,12 | J151: 20/08/2026 | K151: 51781582-663.05[38420]-55284 | L151: 016252 | M151: YILDIRIM VERGİ DAİRESİ
A154: AÇIKLAMA | B154: SORUMLU | C154: RAPOR KAYIT DEFTERİ NUMARASI | D154: İHBARNAME FİŞ NUMARASI | E154: RAPOR TARİHİ | F154: RAPOR SAYISI | G154: RAPOR TÜRÜ | H154: VERGİ KİMLİK NUMARASI | I154: UNVAN | J154: VERGİ KODU | K154: DÖNEM | L154: YAZI TARİHİ | M154: YAZI SAYISI | N154: VERGİ DAİRESİ KODU | O154: VERGİ DAİRESİ ADI | P154: İHBARNAME TARH EDİLEN TUTAR | Q154: RAPOR TARH ÖNERİLEN TUTAR | R154: FARK
A155: 03.06 - Vergi İnceleme Raporlarında Yer alan Vergi Tutarları ile İhbarnamelerde Yer Alan Vergi Tutarları Arasında Fark Olanların Listesi | B155: Hikmet ŞAHİN | C155: 2026041450QAJ0000002 | D155: 2026041413QAI0000004 | E155: 24/02/2026 | F155: 2026-[2014-1-508]/14 | G155: VİR | H155: 8620377585 | I155: EMRECAN TUNALI | J155: 0032 | K155: 202201202203 | L155: 02/03/2026 | M155: 51781582-663.05[52737]-10506 | N155: 016252 | O155: YILDIRIM VERGİ DAİRESİ | P155: 0 | Q155: 11382.28 | R155: 11382.28

Sheet 05 TAKDİRİ SEVK İŞLEMLERİ
A2: AÇIKLAMA | B2: SORUMLU | C2: TAKDİR KOMİSYONU KARAR NUMARASI | D2: TAKDİR KOMİSYONU KARAR TARİHİ | E2: TAKDİR KOMİSYONUNA SEVK NUMARASI | F2: TAKDİR KOMİSYONUNA SEVK TARİHİ | G2: VERGİ KİMLİK NUMARASI | H2: AD SOYAD/UNVAN | I2: VERGİ KODU | J2: VERGİLENDİRME DÖNEMİ | K2: FARK
A3: 05.05 - Takdir Komisyonu Kararı Olmasına Rağmen Vergi Ceza İhbarnamesi Düzenlenmeyen Mükellefler Listesi | B3: Ahmet TARANCI | C3: 627 | D3: 28/03/2023 | E3: 2023032006Q9k0000008 | F3: 20/03/2023 | G3: 3850151938 | H3: AYDIN FATURACI | I3: 0032 | J3: 202104202106 | K3: 2363.3
A4: 05.05 - Takdir Komisyonu Kararı Olmasına Rağmen Vergi Ceza İhbarnamesi Düzenlenmeyen Mükellefler Listesi | B4: Ahmet TARANCI | C4: 628 | D4: 28/03/2023 | E4: 2023032006Q9k0000009 | F4: 20/03/2023 | G4: 3850151938 | H4: AYDIN FATURACI | I4: 0032 | J4: 202107202109 | K4: 2363.3
A5: 05.05 - Takdir Komisyonu Kararı Olmasına Rağmen Vergi Ceza İhbarnamesi Düzenlenmeyen Mükellefler Listesi | B5: Nuran KARAKAYA | C5: 3574 | D5: 19/12/2022 | E5: 2022120506Q9l0000017 | F5: 06/12/2022 | G5: 4990117663 | H5: OĞUZHAN KAPLAY | I5: 0032 | J5: 202204202206 | K5: 340180.8
A6: 05.05 - Takdir Komisyonu Kararı Olmasına Rağmen Vergi Ceza İhbarnamesi Düzenlenmeyen Mükellefler Listesi | B6: Nur Berru YENİÇERİ | C6: 3704 | D6: 16/09/2025 | E6: 2025032406Q9m0000025 | F6: 27/03/2025 | G6: 5960525464 | H6: GÜVEN KURTULUŞ | I6: 0032 | J6: 202110202112 | K6: 1742.45
A7: 05.05 - Takdir Komisyonu Kararı Olmasına Rağmen Vergi Ceza İhbarnamesi Düzenlenmeyen Mükellefler Listesi | B7: Özge TARIM | C7: 165 | D7: 29/02/2024 | E7: 2023112106Q9i0000015 | F7: 22/11/2023 | G7: 1120867371 | H7: İBRAHİM AYDIN | I7: 0032 | J7: 202110202112 | K7: 26695
A8: 05.05 - Takdir Komisyonu Kararı Olmasına Rağmen Vergi Ceza İhbarnamesi Düzenlenmeyen Mükellefler Listesi | B8: Resul MEYDAN | C8: 4830 | D8: 18/12/2025 | E8: 2025070306Q9l0000010 | F8: 21/07/2025 | G8: 4740009677 | H8: İSMAİL HAKKI KURAN KURSU İMAM-HATİP VE İLAHİYAT ÖĞRENCİLERİNE YARDIM DERNEĞİ | I8: 0003 | J8: 202112202112 | K8: 22550
A9: 05.05 - Takdir Komisyonu Kararı Olmasına Rağmen Vergi Ceza İhbarnamesi Düzenlenmeyen Mükellefler Listesi | B9: Canan YILDIZOĞLU | C9: 539 | D9: 04/04/2024 | E9: 2024031506Q9o0000018 | F9: 21/03/2024 | G9: 7300715496 | H9: PLAS GERİ DÖNÜŞÜM PLASTİK POLİMER ORMAN ÜRÜNLERİ İNŞAAT İTHALAT İHRACAT İMALAT SAN.VE TİC.LTD.ŞTİ. | I9: 0033 | J9: 202207202209 | K9: 75824.68
A10: 05.05 - Takdir Komisyonu Kararı Olmasına Rağmen Vergi Ceza İhbarnamesi Düzenlenmeyen Mükellefler Listesi | B10: Nuran KARAKAYA | C10: 2503 | D10: 04/11/2024 | E10: 2024092606Q9m0000010 | F10: 01/10/2024 | G10: 5241293654 | H10: KARDEŞLER COMPANY DIŞ TİCARET LİMİTED ŞİRKETİ | I10: 0015 | J10: 202404202404 | K10: 9900
A14: AÇIKLAMA | B14: SORUMLU | C14: TAKDİR KOMİSYONUNA SEVK NUMARASI | D14: TAKDİR KOMİSYONUNA SEVK TARİHİ | E14: VERGİ KİMLİK NUMARASI | F14: AD SOYAD/UNVAN | G14: VERGİ KODU | H14: VERGİLENDİRME DÖNEMİ | I14: İHBARNAME FİŞ NUMARASI | J14: CEZA TUTARI
A15: 05.04 - Elektronik Ortamda Beyanname Vermesi Gereken Mükelleflerden Takdire Sevk Edildiği Halde Özel Usulsüzlük Cezası Kesilmeyenlerin Listesi | B15: Hikmet ŞAHİN | C15: 2022070106Q9q0000021 | D15: 02/09/2022 | E15: 9040130518 | F15: NİHAT UZUNORMAN | G15: 0032 | H15: 202107202109
A16: 05.04 - Elektronik Ortamda Beyanname Vermesi Gereken Mükelleflerden Takdire Sevk Edildiği Halde Özel Usulsüzlük Cezası Kesilmeyenlerin Listesi | B16: Ali BEŞTAŞ | C16: 2022101406Q9o0000069 | D16: 18/10/2022 | E16: 7410277277 | F16: MUSTAFA SALIK | G16: 0015 | H16: 202101202101
A17: 05.04 - Elektronik Ortamda Beyanname Vermesi Gereken Mükelleflerden Takdire Sevk Edildiği Halde Özel Usulsüzlük Cezası Kesilmeyenlerin Listesi | B17: Ali BEŞTAŞ | C17: 2022101406Q9o0000070 | D17: 18/10/2022 | E17: 7410277277 | F17: MUSTAFA SALIK | G17: 0015 | H17: 202102202102
A18: 05.04 - Elektronik Ortamda Beyanname Vermesi Gereken Mükelleflerden Takdire Sevk Edildiği Halde Özel Usulsüzlük Cezası Kesilmeyenlerin Listesi | B18: Ali BEŞTAŞ | C18: 2022101406Q9o0000071 | D18: 18/10/2022 | E18: 7410277277 | F18: MUSTAFA SALIK | G18: 0015 | H18: 202103202103
A19: 05.04 - Elektronik Ortamda Beyanname Vermesi Gereken Mükelleflerden Takdire Sevk Edildiği Halde Özel Usulsüzlük Cezası Kesilmeyenlerin Listesi | B19: Ali BEŞTAŞ | C19: 2022101406Q9o0000072 | D19: 18/10/2022 | E19: 7410277277 | F19: MUSTAFA SALIK | G19: 0015 | H19: 202104202104
A20: 05.04 - Elektronik Ortamda Beyanname Vermesi Gereken Mükelleflerden Takdire Sevk Edildiği Halde Özel Usulsüzlük Cezası Kesilmeyenlerin Listesi | B20: Ali BEŞTAŞ | C20: 2022101406Q9o0000073 | D20: 18/10/2022 | E20: 7410277277 | F20: MUSTAFA SALIK | G20: 0015 | H20: 202105202105
A21: 05.04 - Elektronik Ortamda Beyanname Vermesi Gereken Mükelleflerden Takdire Sevk Edildiği Halde Özel Usulsüzlük Cezası Kesilmeyenlerin Listesi | B21: Ali BEŞTAŞ | C21: 2022101406Q9o0000074 | D21: 18/10/2022 | E21: 7410277277 | F21: MUSTAFA SALIK | G21: 0015 | H21: 202106202106
A22: 05.04 - Elektronik Ortamda Beyanname Vermesi Gereken Mükelleflerden Takdire Sevk Edildiği Halde Özel Usulsüzlük Cezası Kesilmeyenlerin Listesi | B22: Ali BEŞTAŞ | C22: 2022101406Q9o0000075 | D22: 18/10/2022 | E22: 7410277277 | F22: MUSTAFA SALIK | G22: 0015 | H22: 202107202107
A23: 05.04 - Elektronik Ortamda Beyanname Vermesi Gereken Mükelleflerden Takdire Sevk Edildiği Halde Özel Usulsüzlük Cezası Kesilmeyenlerin Listesi | B23: Ali BEŞTAŞ | C23: 2022101406Q9o0000076 | D23: 18/10/2022 | E23: 7410277277 | F23: MUSTAFA SALIK | G23: 0032 | H23: 202101202103
A24: 05.04 - Elektronik Ortamda Beyanname Vermesi Gereken Mükelleflerden Takdire Sevk Edildiği Halde Özel Usulsüzlük Cezası Kesilmeyenlerin Listesi | B24: Ali BEŞTAŞ | C24: 2022101406Q9o0000077 | D24: 18/10/2022 | E24: 7410277277 | F24: MUSTAFA SALIK | G24: 0032 | H24: 202104202106
A25: 05.04 - Elektronik Ortamda Beyanname Vermesi Gereken Mükelleflerden Takdire Sevk Edildiği Halde Özel Usulsüzlük Cezası Kesilmeyenlerin Listesi | B25: Ali BEŞTAŞ | C25: 2022101406Q9o0000078 | D25: 18/10/2022 | E25: 7410277277 | F25: MUSTAFA SALIK | G25: 0032 | H25: 202107202109
A26: 05.04 - Elektronik Ortamda Beyanname Vermesi Gereken Mükelleflerden Takdire Sevk Edildiği Halde Özel Usulsüzlük Cezası Kesilmeyenlerin Listesi | B26: Ali BEŞTAŞ | C26: 2022101406Q9o0000079 | D26: 18/10/2022 | E26: 7410277277 | F26: MUSTAFA SALIK | G26: 0001 | H26: 202101202112
... A30: 05.04 - Elektronik Ortamda Beyanname Vermesi Gereken Mükelleflerden Takdire Sevk Edildiği Halde Özel Usulsüzlük Cezası Kesilmeyenlerin Listesi | B30: Hikmet ŞAHİN | C30: 2025120806Q9p0000004 | D30: 22/12/2025 | E30: 8210331453 | F30: AYTUĞ TANRIKULU | G30: 0032 | H30: 202501202503
A33: AÇIKLAMA | B33: SORUMLU | C33: VERGİ KİMLİK NUMARASI | D33: T.C. KİMLİK NUMARASI | E33: AD SOYAD/UNVAN | F33: VERGİ KODU | G33: VERGİLENDİRME DÖNEMİ
A34: 05.03 - Katma Değer Vergisi Beyannamesini Vermeyen Mükellefler Arasından Takdir Komisyonuna Sevk Edilmeyenlerin Listesi | B34: Halim YARAR | C34: 1910567473 | E34: BURSA SOSYAL GÜVENLİK İL MÜDÜRLÜĞÜ MİSAFİRHANE İŞLETMESİ. | F34: 0015 | G34: 202101202101
A35: 05.03 - Katma Değer Vergisi Beyannamesini Vermeyen Mükellefler Arasından Takdir Komisyonuna Sevk Edilmeyenlerin Listesi | B35: Halim YARAR | C35: 1911292067 | E35: BURSA ATLISPOR KULÜBÜ DERNEĞİ İKTİSADİ İŞLETMESİ | F35: 0015 | G35: 202101202101
A36: 05.03 - Katma Değer Vergisi Beyannamesini Vermeyen Mükellefler Arasından Takdir Komisyonuna Sevk Edilmeyenlerin Listesi | B36: Çağatay TÜRKOĞLU | C36: 2711220900 | D36: 53620466732 | E36: HAYRİYE KARAGÜL | F36: 0015 | G36: 202101202101
A37: 05.03 - Katma Değer Vergisi Beyannamesini Vermeyen Mükellefler Arasından Takdir Komisyonuna Sevk Edilmeyenlerin Listesi | B37: Resul MEYDAN | C37: 4780910241 | E37: TASF.HAL.İNG YABANCI DİL AKADEMİK KURSLARI EĞİTİM TİCARET LİMİTED ŞİRKETİ | F37: 0015 | G37: 202101202101
A38: 05.03 - Katma Değer Vergisi Beyannamesini Vermeyen Mükellefler Arasından Takdir Komisyonuna Sevk Edilmeyenlerin Listesi | B38: Ali BEŞTAŞ | C38: 7750410574 | E38: BURSA SOSYAL GÜVENLİK KURUMU İL MÜDÜRLÜĞÜ PERSONELİ TABLDOT İŞLETME SERVİSİ | F38: 0015 | G38: 202101202101
A39: 05.03 - Katma Değer Vergisi Beyannamesini Vermeyen Mükellefler Arasından Takdir Komisyonuna Sevk Edilmeyenlerin Listesi | B39: Ömer DÜNDAR | C39: 9720314103 | D39: 10660938070 | E39: MEHMET YILMAZ | F39: 0015 | G39: 202101202101
A40: 05.03 - Katma Değer Vergisi Beyannamesini Vermeyen Mükellefler Arasından Takdir Komisyonuna Sevk Edilmeyenlerin Listesi | B40: Hikmet ŞAHİN | C40: 8250327209 | E40: TASF.HAL.SINIRLI SORUMLU TASARIM KONUT YAPI KOOPERATİFİ | F40: 0015 | G40: 202101202103
A41: 05.03 - Katma Değer Vergisi Beyannamesini Vermeyen Mükellefler Arasından Takdir Komisyonuna Sevk Edilmeyenlerin Listesi | B41: Halim YARAR | C41: 1910567473 | E41: BURSA SOSYAL GÜVENLİK İL MÜDÜRLÜĞÜ MİSAFİRHANE İŞLETMESİ. | F41: 0015 | G41: 202102202102
A42: 05.03 - Katma Değer Vergisi Beyannamesini Vermeyen Mükellefler Arasından Takdir Komisyonuna Sevk Edilmeyenlerin Listesi | B42: Halim YARAR | C42: 1911292067 | E42: BURSA ATLISPOR KULÜBÜ DERNEĞİ İKTİSADİ İŞLETMESİ | F42: 0015 | G42: 202102202102
A43: 05.03 - Katma Değer Vergisi Beyannamesini Vermeyen Mükellefler Arasından Takdir Komisyonuna Sevk Edilmeyenlerin Listesi | B43: Çağatay TÜRKOĞLU | C43: 2711220900 | D43: 53620466732 | E43: HAYRİYE KARAGÜL | F43: 0015 | G43: 202102202102
A44: 05.03 - Katma Değer Vergisi Beyannamesini Vermeyen Mükellefler Arasından Takdir Komisyonuna Sevk Edilmeyenlerin Listesi | B44: Resul MEYDAN | C44: 4780910241 | E44: TASF.HAL.İNG YABANCI DİL AKADEMİK KURSLARI EĞİTİM TİCARET LİMİTED ŞİRKETİ | F44: 0015 | G44: 202102202102
A45: 05.03 - Katma Değer Vergisi Beyannamesini Vermeyen Mükellefler Arasından Takdir Komisyonuna Sevk Edilmeyenlerin Listesi | B45: Ali BEŞTAŞ | C45: 7750410574 | E45: BURSA SOSYAL GÜVENLİK KURUMU İL MÜDÜRLÜĞÜ PERSONELİ TABLDOT İŞLETME SERVİSİ | F45: 0015 | G45: 202102202102
A46: 05.03 - Katma Değer Vergisi Beyannamesini Vermeyen Mükellefler Arasından Takdir Komisyonuna Sevk Edilmeyenlerin Listesi | B46: Halim YARAR | C46: 1910567473 | E46: BURSA SOSYAL GÜVENLİK İL MÜDÜRLÜĞÜ MİSAFİRHANE İŞLETMESİ. | F46: 0015 | G46: 202103202103
A47: 05.03 - Katma Değer Vergisi Beyannamesini Vermeyen Mükellefler Arasından Takdir Komisyonuna Sevk Edilmeyenlerin Listesi | B47: Halim YARAR | C47: 1911292067 | E47: BURSA ATLISPOR KULÜBÜ DERNEĞİ İKTİSADİ İŞLETMESİ | F47: 0015 | G47: 202103202103
A48: 05.03 - Katma Değer Vergisi Beyannamesini Vermeyen Mükellefler Arasından Takdir Komisyonuna Sevk Edilmeyenlerin Listesi | B48: Resul MEYDAN | C48: 4780910241 | E48: TASF.HAL.İNG YABANCI DİL AKADEMİK KURSLARI EĞİTİM TİCARET LİMİTED ŞİRKETİ | F48: 0015 | G48: 202103202103
A49: 05.03 - Katma Değer Vergisi Beyannamesini Vermeyen Mükellefler Arasından Takdir Komisyonuna Sevk Edilmeyenlerin Listesi | B49: Ali BEŞTAŞ | C49: 7750410574 | E49: BURSA SOSYAL GÜVENLİK KURUMU İL MÜDÜRLÜĞÜ PERSONELİ TABLDOT İŞLETME SERVİSİ | F49: 0015 | G49: 202103202103
...

Sheet 06 VERGİ CEZA İHBARNAMELERİ
A2: AÇIKLAMA | B2: SORUMLU | C2: VERGİ KİMLİK NUMARASI | D2: UNVAN | E2: TAHAKKUK FİŞ NUMARASI | F2: DÖNEM | G2: ANA VERGİ KODU | H2: VERGİ KODU | I2: TAHAKKUK TOPLAMI | J2: TAHSİLAT TOPLAMI
A3: 06.04 - Ödenmediği Halde Terkin Edilmeyen Geçici Vergi Tahakkukları Listesi | B3: Özge TARIM | C3: 1271222714 | D3: B R ÖZTEKİN İNŞAAT OTOMOTİV ORMAN ÜRÜNLERİ LİMİTED ŞİRKETİ | E3: 2026022001QB60000020 | F3: 202404202406 | G3: 0033 | H3: 0033 | I3: 3825 | J3: 0
